Workbook

Sheet READ_ME
B2: Tabs | C2: Details | D2: Notes | F2: Abbreviations
B3: HAWC2 | C3: Raw data of noFPM & FPM structural models of HAWC2 | D3: Compare them to map matrix elements with structural properties | F3: FPM | G3: Fully Populated Matrix
B4: HAWC2_2_hGAST_noFPM | C4: Process noFPM data to use as input in hGAST | D4: HAWC2 in airfoil LOCAL system, tranformation to hGAST blade GLOBAL system | F4: 2 | G4: to
B5: HAWC2_2_hGAST_FPM | C5: Process FPM data to use as input in hGAST | D5: HAWC2 in airfoil LOCAL system, tranformation to hGAST blade GLOBAL system
B6: hGAST_comparison | C6: Comparison of noFPM & FPM hGAST models | D6: Plots of "HAWC2_2_hGAST_***" tabs
B7: hGAST_vs_BeamDyn | C7: Raw IEA data compared with noFPM & FPM hGAST models | D7: IEA data given in BeamDyn format | F7: vs | G7: versus
B8: BeamDyn_2_hGAST | C8: Process BeamDyn FPM data to use as input in hGAST | D8: BeamDyn in airfoil LOCAL system, tranformation to hGAST blade GLOBAL system
B9: machi_frm_BeamDyn | C9: Model in machi.inp format | D9: "BeamDyn_2_hGAST" model | F9: frm | G9: from
B10: machi_frm_HAWC2 | C10: Model in machi.inp format | D10: "HAWC2_2_hGAST_FPM" model
B11: EXI_BeamDyn_diff | C11: Comparison of "BeamDyn_2_hGAST" & "EXI_machi" models | D11: plots, [%] differences | F11: diff | G11: differences
B12: EXI_HAWC2_diff | C12: Comparison of "HAWC2_2_hGAST_FPM" & "EXI_machi" models | D12: plots, [%] differences
B13: tower+shaft | C13: Process tower & shaft structural properties | D13: HAWC2 data
B14: output | C14: TXT format of machi.inp | D14: "machi_frm_BeamDyn"
B15: EXI_machi | C15: Existing machi.inp | D15: Manolo's machi.inp | F15: EXI | G15: existing

Sheet HAWC2
A1: HAWC_2 | V1: HAWC_2 | AJ1: HAWC_2
A2: File Name: | B2: https://github.com/IEAWindSystems/IEA-15-240-RWT/blob/master/HAWC2/IEA-15-240-RWT/IEA_15MW_RWT_Blade_st_noFPM.st | AJ2: File Name: | AK2: https://github.com/IEAWindSystems/IEA-15-240-RWT/blob/master/HAWC2/IEA-15-240-RWT/IEA_15MW_RWT_Blade_st_FPM.st
A3: Details: | B3: RAW | C3: DATA | D3: Structural properties for blade model: standard Timoshenko beam | V3: Details: | W3: PROCESS | X3: noFPM.st data to compare with FPM data (stiffness matrix elements) | AJ3: Details: | AK3: RAW | AL3: DATA | AM3: Structural properties for blade model: fully-populated matrix (FPM) | AS3: Shr_edg | AT3: Shr_flp-edg | AX3: Shr_edg + Trs | AY3: Shr_flp | BC3: Shr_flp + Trs | BD3: Ten | BE3: Ten + Bnd_flp | BF3: Ten + Bnd_edg | BH3: Bnd_flp | BI3: Bnd_flp-edg | BK3: Bnd_edg | BM3: Trs
V4: Notes: | W4: shear - torsion coupling | X4: principal | Y4: principal | AA4: principal | AB4: principal | AC4: principal | AD4: principal | AF4: principal | AG4: @ elastic center | AH4: @ elastic center | AJ4: Notes: | AS4: GAx | AT4: GΑxy | AX4: - GAxX | AY4: GAy | BC4: GAyY | BD4: EA | BE4: EAx | BF4: - EAy | BH4: EIxx | BI4: - EIxy | BK4: EIyy | BM4: GJ
A5: r_[m] | B5: m_[kg/m] | C5: x_cg_[m] | D5: y_cg_[m] | E5: ri_x_[m] | F5: ri_y_[m] | G5: x_sh_[m] | H5: y_sh_[m] | I5: E_[N/m^2] | J5: G_[N/m^2] | K5: I_x_[m^4] | L5: I_y_[m^4] | M5: I_p_[m^4] | N5: k_x_[-] | O5: k_y_[-] | P5: A_[m^2] | Q5: pitch_[deg] | R5: x_e_[m] | S5: y_e_[m] | T5: $ 26 | V5: c2_GAxX_[Nm] | W5: c2_GAyY_[Nm] | X5: GAx_[N] | Y5: GAy_[N] | Z5: EA_[N] | AA5: - GAxX_[Nm] | AB5: GAyY_[Nm] | AC5: EIxx_[Nm2] | AD5: EIyy_[Nm2] | AE5: GJ_[Nm2] | AF5: EIxy_[Nm2] | AG5: EAx_[Nm] | AH5: EAy_[Nm] | AJ5: r | AK5: m_[kg/m] | AL5: x_cg_[m] | AM5: y_cg_[m] | AN5: ri_x_[m] | AO5: ri_y_[m] | AP5: pitch_[deg] | AQ5: x_e_[m] | AR5: y_e_[m] | AS5: K11 | AT5: K12 | AU5: K13 | AV5: K14 | AW5: K15 | AX5: K16 | AY5: K22 | AZ5: K23 | BA5: K24 | BB5: K25 | BC5: K26 | BD5: K33 | BE5: K34 | BF5: K35 | BG5: K36 | BH5: K44 | BI5: K45 | BJ5: K46 | BK5: K55 | BL5: K56 | BM5: K66
A6: 0 | B6: 3126.5244 | C6: 0.00011619906 | D6: -0.00014234568 | E6: 1.8027984 | F6: 1.8021313 | G6: -0.001501774 | H6: 0.005716245 | I6: 1.8877163e+10 | J6: 3.9142658e+09 | K6: 7.9258187 | L6: 7.9176781 | M6: 22.331655 | N6: 0.71414345 | O6: 0.71547347 | P6: 2.4063482 | Q6: -6.0000871 | R6: 0.00019957381 | S6: -0.0004766766 | T6: 1 | V6: =V67*(H6-S6) -> 41657262 | W6: =W67*(G6-R6) -> -11465540 | X6: =N6*$J6*$P6 -> 6.7265789e+09 | Y6: =O6*$J6*$P6 -> 6.7391065e+09 | Z6: =I6*P6 -> 4.5425027e+10 | AA6: =- V6*COS(Q6*PI()/180) + W6*SIN(Q6*PI()/180) -> -40230560 | AB6: =V6*SIN($Q6*PI()/180) + W6*COS($Q6*PI()/180) -> -15757162 | AC6: =$I6*K6 -> 1.4961697e+11 | AD6: =$I6*L6 -> 1.494633e+11 | AE6: =J6*M6 -> 8.7412032e+10 | AF6: 0 | AG6: =$Z6*(R6-R6) -> 0 | AH6: =$Z6*(S6-S6) -> 0 | AJ6: 0 | AK6: 3126.5244 | AL6: 0.00011619906 | AM6: -0.00014234568 | AN6: 1.8027984 | AO6: 1.8021313 | AP6: -6.000087 | AQ6: 0.00019957381 | AR6: -0.0004766766 | AS6: 6.7269806e+09 | AT6: -2207086.4 | AU6: 0 | AV6: 0 | AW6: 0 | AX6: -40229939 | AY6: 6.7387047e+09 | AZ6: 0 | BA6: 0 | BB6: 0 | BC6: -15751145 | BD6: 4.6038157e+10 | BE6: 0 | BF6: 0 | BG6: 0 | BH6: 1.4961697e+11 | BI6: 0.0037733711 | BJ6: 0 | BK6: 1.494633e+11 | BL6: 0 | BM6: 8.7412309e+10
A7: 1.1717945 | B7: 2963.782 | C7: 1.6504997e-05 | D7: -3.0532716e-05 | E7: 1.8062497 | F7: 1.8053424 | G7: -0.0012883452 | H7: 0.0026252488 | I7: 1.8584497e+10 | J7: 3.8423282e+09 | K7: 7.6975357 | L7: 7.6477503 | M7: 21.654596 | N7: 0.71552541 | O7: 0.71494667 | P7: 2.3231772 | Q7: 12.238819 | R7: 8.7271317e-05 | S7: -4.9605487e-05 | T7: 2 | V7: =V68*(H7-S7) -> 17084425 | W7: =W68*(G7-R7) -> -8779089.2 | X7: =N7*$J7*$P7 -> 6.3870727e+09 | Y7: =O7*$J7*$P7 -> 6.3819066e+09 | Z7: =I7*P7 -> 4.317508e+10 | AA7: =- V7*COS(Q7*PI()/180) + W7*SIN(Q7*PI()/180) -> -18557191 | AB7: =V7*SIN($Q7*PI()/180) + W7*COS($Q7*PI()/180) -> -4957887.1 | AC7: =$I7*K7 -> 1.4305483e+11 | AD7: =$I7*L7 -> 1.4212959e+11 | AE7: =J7*M7 -> 8.3204064e+10 | AF7: 0 | AG7: =$Z7*(R7-R7) -> 0 | AH7: =$Z7*(S7-S7) -> 0 | AJ7: 1.1717945 | AK7: 2963.782 | AL7: 1.6504997e-05 | AM7: -3.0532716e-05 | AN7: 1.8062497 | AO7: 1.8053424 | AP7: 12.238819 | AQ7: 8.7271317e-05 | AR7: -4.9605487e-05 | AS7: 6.3866374e+09 | AT7: 1434921.8 | AU7: 0 | AV7: 0 | AW7: 0 | AX7: -18558603 | AY7: 6.3823418e+09 | AZ7: 0 | BA7: 0 | BB7: 0 | BC7: -4965278.6 | BD7: 4.3737323e+10 | BE7: 0 | BF7: 0 | BG7: 0 | BH7: 1.4305483e+11 | BI7: 0.0014962521 | BJ7: 0 | BK7: 1.4212959e+11 | BL7: 0 | BM7: 8.3204122e+10
A8: 2.343589 | B8: 2803.2194 | C8: -0.00041240989 | D8: 0.0021601408 | E8: 1.8084173 | F8: 1.8078245 | G8: -0.00033057121 | H8: 0.0021861867 | I8: 1.8291831e+10 | J8: 3.7703907e+09 | K8: 7.4777003 | L8: 7.3682492 | M8: 20.934016 | N8: 0.71729255 | O8: 0.71309084 | P8: 2.2400061 | Q8: 14.368451 | R8: -7.1633937e-05 | S8: 0.002263701 | T8: 3 | V8: =V69*(H8-S8) -> -469566.98 | W8: =W69*(G8-R8) -> -1559521.1 | X8: =N8*$J8*$P8 -> 6.0580365e+09 | Y8: =O8*$J8*$P8 -> 6.0225501e+09 | Z8: =I8*P8 -> 4.0973815e+10 | AA8: =- V8*COS(Q8*PI()/180) + W8*SIN(Q8*PI()/180) -> 67873.58 | AB8: =V8*SIN($Q8*PI()/180) + W8*COS($Q8*PI()/180) -> -1627265.4 | AC8: =$I8*K8 -> 1.3678083e+11 | AD8: =$I8*L8 -> 1.3477877e+11 | AE8: =J8*M8 -> 7.8929419e+10 | AF8: 0 | AG8: =$Z8*(R8-R8) -> 0 | AH8: =$Z8*(S8-S8) -> 0 | AJ8: 2.343589 | AK8: 2803.2194 | AL8: -0.00041240989 | AM8: 0.0021601408 | AN8: 1.8084173 | AO8: 1.8078245 | AP8: 14.368451 | AQ8: -7.1633937e-05 | AR8: 0.002263701 | AS8: 6.0578285e+09 | AT8: 2708485.6 | AU8: 0 | AV8: 0 | AW8: 0 | AX8: 64891.037 | AY8: 6.0227581e+09 | AZ8: 0 | BA8: 0 | BB8: 0 | BC8: -1626557.3 | BD8: 4.1541388e+10 | BE8: -1.4550609e-08 | BF8: 3.2467247e-09 | BG8: 0 | BH8: 1.3678083e+11 | BI8: 0.00024676218 | BJ8: 0 | BK8: 1.3477877e+11 | BL8: 0 | BM8: 7.8929419e+10
A9: 3.5153835 | B9: 2590.6426 | C9: 0.020387902 | D9: 0.006677439 | E9: 1.7470076 | F9: 1.7954732 | G9: 0.022315105 | H9: 0.0067721136 | I9: 1.7999166e+10 | J9: 3.6984531e+09 | K9: 6.6112419 | L9: 6.860285 | M9: 18.90384 | N9: 0.72180968 | O9: 0.67678235 | P9: 2.1568351 | Q9: -18.270906 | R9: 0.021511267 | S9: 0.0068865104 | T9: 4 | V9: =V70*(H9-S9) -> -658257.02 | W9: =W70*(G9-R9) -> 4342613.8 | X9: =N9*$J9*$P9 -> 5.7578424e+09 | Y9: =O9*$J9*$P9 -> 5.3986614e+09 | Z9: =I9*P9 -> 3.8821233e+10 | AA9: =- V9*COS(Q9*PI()/180) + W9*SIN(Q9*PI()/180) -> -736383.35 | AB9: =V9*SIN($Q9*PI()/180) + W9*COS($Q9*PI()/180) -> 4330050.4 | AC9: =$I9*K9 -> 1.1899684e+11 | AD9: =$I9*L9 -> 1.2347941e+11 | AE9: =J9*M9 -> 6.9914965e+10 | AF9: 0 | AG9: =$Z9*(R9-R9) -> 0 | AH9: =$Z9*(S9-S9) -> 0 | AJ9: 3.5153835 | AK9: 2590.6426 | AL9: 0.020387902 | AM9: 0.006677439 | AN9: 1.7470076 | AO9: 1.7954732 | AP9: -18.270906 | AQ9: 0.021511267 | AR9: 0.0068865104 | AS9: 5.723816e+09 | AT9: 1.0518475e+08 | AU9: 0 | AV9: 0 | AW9: 0 | AX9: -736631.02 | AY9: 5.4326878e+09 | AZ9: 0 | BA9: 0 | BB9: 0 | BC9: 4326597.2 | BD9: 3.8662608e+10 | BE9: 0 | BF9: 0 | BG9: 0 | BH9: 1.1899684e+11 | BI9: -0.00037510227 | BJ9: 0 | BK9: 1.2347941e+11 | BL9: 0 | BM9: 6.9914969e+10
A10: 4.6871779 | B10: 2388.5133 | C10: 0.042572706 | D10: 0.0085154764 | E10: 1.6836286 | F10: 1.78186 | G10: 0.05084388 | H10: 0.008616737 | I10: 1.7778652e+10 | J10: 3.6329925e+09 | K10: 5.8347272 | L10: 6.3227219 | M10: 16.919384 | N10: 0.72922423 | O10: 0.64000623 | P10: 2.0641301 | Q10: -14.547717 | R10: 0.045156431 | S10: 0.0088398777 | T10: 5 | V10: =V71*(H10-S10) -> -1219256.2 | W10: =W71*(G10-R10) -> 27321071 | X10: =N10*$J10*$P10 -> 5.4684302e+09 | Y10: =O10*$J10*$P10 -> 4.7993871e+09 | Z10: =I10*P10 -> 3.669745e+10 | AA10: =- V10*COS(Q10*PI()/180) + W10*SIN(Q10*PI()/180) -> -5682511.1 | AB10: =V10*SIN($Q10*PI()/180) + W10*COS($Q10*PI()/180) -> 26751385 | AC10: =$I10*K10 -> 1.0373358e+11 | AD10: =$I10*L10 -> 1.1240947e+11 | AE10: =J10*M10 -> 6.1467995e+10 | AF10: 0 | AG10: =$Z10*(R10-R10) -> 0 | AH10: =$Z10*(S10-S10) -> 0 | AJ10: 4.6871779 | AK10: 2388.5133 | AL10: 0.042572706 | AM10: 0.0085154764 | AN10: 1.6836286 | AO10: 1.78186 | AP10: -14.547717 | AQ10: 0.045156431 | AR10: 0.0088398777 | AS10: 5.4290704e+09 | AT10: 1.5742995e+08 | AU10: 0 | AV10: 0 | AW10: 0 | AX10: -5707919.9 | AY10: 4.8387469e+09 | AZ10: 0 | BA10: 0 | BB10: 0 | BC10: 26718106 | BD10: 3.6029912e+10 | BE10: 0 | BF10: 0 | BG10: 0 | BH10: 1.0373358e+11 | BI10: 0.0011268719 | BJ10: 0 | BK10: 1.1240947e+11 | BL10: 0 | BM10: 6.1468151e+10
A11: 5.8589724 | B11: 2202.7745 | C11: 0.065015869 | D11: 0.010016937 | E11: 1.6236674 | F11: 1.7716164 | G11: 0.085038131 | H11: 0.010073143 | I11: 1.7558138e+10 | J11: 3.567532e+09 | K11: 5.1896091 | L11: 5.861944 | M11: 15.154369 | N11: 0.73871737 | O11: 0.60349432 | P11: 1.9714251 | Q11: -14.738774 | R11: 0.069820297 | S11: 0.010313881 | T11: 6 | V11: =V72*(H11-S11) -> -1249220.6 | W11: =W72*(G11-R11) -> 64688144 | X11: =N11*$J11*$P11 -> 5.1954894e+09 | Y11: =O11*$J11*$P11 -> 4.2444492e+09 | Z11: =I11*P11 -> 3.4614553e+10 | AA11: =- V11*COS(Q11*PI()/180) + W11*SIN(Q11*PI()/180) -> -15249355 | AB11: =V11*SIN($Q11*PI()/180) + W11*COS($Q11*PI()/180) -> 62877450 | AC11: =$I11*K11 -> 9.1119871e+10 | AD11: =$I11*L11 -> 1.0292482e+11 | AE11: =J11*M11 -> 5.4063694e+10 | AF11: 0 | AG11: =$Z11*(R11-R11) -> 0 | AH11: =$Z11*(S11-S11) -> 0 | AJ11: 5.8589724 | AK11: 2202.7745 | AL11: 0.065015869 | AM11: 0.010016937 | AN11: 1.6236674 | AO11: 1.7716164 | AP11: -14.738774 | AQ11: 0.069820297 | AR11: 0.010313881 | AS11: 5.136725e+09 | AT11: 2.2898473e+08 | AU11: 0 | AV11: 0 | AW11: 0 | AX11: -15307448 | AY11: 4.3032135e+09 | AZ11: 0 | BA11: 0 | BB11: 0 | BC11: 62761172 | BD11: 3.3734996e+10 | BE11: -5.7643402e-08 | BF11: -1.5164165e-08 | BG11: 0 | BH11: 9.1119871e+10 | BI11: -0.0014816443 | BJ11: 0 | BK11: 1.0292482e+11 | BL11: 0 | BM11: 5.4064678e+10
A12: 8.7884587 | B12: 1792.6097 | C12: 0.11917137 | D12: 0.014182574 | E12: 1.4756546 | F12: 1.7474949 | G12: 0.19966693 | H12: 0.014293299 | I12: 1.6453754e+10 | J12: 3.2682486e+09 | K12: 4.0728047 | L12: 5.0453439 | M12: 11.738782 | N12: 0.75251043 | O12: 0.49841292 | P12: 1.8506405 | Q12: -18.27504 | R12: 0.13519899 | S12: 0.013344766 | T12: 7 | V12: =V73*(H12-S12) -> 4302225.1 | W12: =W73*(G12-R12) -> 1.953614e+08 | X12: =N12*$J12*$P12 -> 4.5514489e+09 | Y12: =O12*$J12*$P12 -> 3.0145774e+09 | Z12: =I12*P12 -> 3.0449985e+10 | AA12: =- V12*COS(Q12*PI()/180) + W12*SIN(Q12*PI()/180) -> -65346427 | AB12: =V12*SIN($Q12*PI()/180) + W12*COS($Q12*PI()/180) -> 1.841587e+08 | AC12: =$I12*K12 -> 6.7012929e+10 | AD12: =$I12*L12 -> 8.3014849e+10 | AE12: =J12*M12 -> 3.836526e+10 | AF12: 0 | AG12: =$Z12*(R12-R12) -> 0 | AH12: =$Z12*(S12-S12) -> 0 | AJ12: 8.7884587 | AK12: 1792.6097 | AL12: 0.11917137 | AM12: 0.014182574 | AN12: 1.4756546 | AO12: 1.7474949 | AP12: -18.27504 | AQ12: 0.13519899 | AR12: 0.013344766 | AS12: 4.3960504e+09 | AT12: 4.6333447e+08 | AU12: 0 | AV12: 0 | AW12: 0 | AX12: -64603262 | AY12: 3.1699759e+09 | AZ12: 0 | BA12: 0 | BB12: 0 | BC12: 1.8332739e+08 | BD12: 2.9196543e+10 | BE12: 0 | BF12: 0 | BG12: 0 | BH12: 6.7012929e+10 | BI12: -1.6729147e-05 | BJ12: 0 | BK12: 8.3014849e+10 | BL12: 0 | BM12: 3.8377792e+10
A13: 11.717945 | B13: 1693.2124 | C13: 0.13808749 | D13: 0.021494918 | E13: 1.2790562 | F13: 1.6704356 | G13: 0.34375471 | H13: 0.027219286 | I13: 1.5349371e+10 | J13: 2.9689652e+09 | K13: 3.2803526 | L13: 4.6798435 | M13: 8.5590491 | N13: 0.77741891 | O13: 0.46952287 | P13: 1.729856 | Q13: -16.870368 | R13: 0.13663255 | S13: 0.02077681 | T13: 8 | V13: =V74*(H13-S13) -> 25633852 | W13: =W74*(G13-R13) -> 5.0232598e+08 | X13: =N13*$J13*$P13 -> 3.9927321e+09 | Y13: =O13*$J13*$P13 -> 2.4114142e+09 | Z13: =I13*P13 -> 2.6552201e+10 | AA13: =- V13*COS(Q13*PI()/180) + W13*SIN(Q13*PI()/180) -> -1.7030934e+08 | AB13: =V13*SIN($Q13*PI()/180) + W13*COS($Q13*PI()/180) -> 4.7326865e+08 | AC13: =$I13*K13 -> 5.0351348e+10 | AD13: =$I13*L13 -> 7.1832653e+10 | AE13: =J13*M13 -> 2.5411519e+10 | AF13: 0 | AG13: =$Z13*(R13-R13) -> 0 | AH13: =$Z13*(S13-S13) -> 0 | AJ13: 11.717945 | AK13: 1693.2124 | AL13: 0.13808749 | AM13: 0.021494918 | AN13: 1.2790562 | AO13: 1.6704356 | AP13: -16.870368 | AQ13: 0.13663255 | AR13: 0.02077681 | AS13: 3.9153541e+09 | AT13: 3.4113318e+08 | AU13: 0 | AV13: 0 | AW13: 0 | AX13: -1.9250688e+08 | AY13: 2.4887922e+09 | AZ13: 0 | BA13: 0 | BB13: 0 | BC13: 4.6603826e+08 | BD13: 2.7318853e+10 | BE13: 0 | BF13: 0 | BG13: 0 | BH13: 5.0351348e+10 | BI13: -0.00096213958 | BJ13: 0 | BK13: 7.1832653e+10 | BL13: 0 | BM13: 2.5515779e+10
A14: 17.576917 | B14: 1050.5803 | C14: 0.11848604 | D14: 0.022979524 | E14: 0.95109579 | F14: 1.6822735 | G14: 0.80909661 | H14: 0.042160514 | I14: 1.7434447e+10 | J14: 2.599168e+09 | K14: 1.5423875 | L14: 2.8782925 | M14: 3.1069015 | N14: 0.71844763 | O14: 0.28851894 | P14: 1.2418107 | Q14: -12.148812 | R14: 0.22787449 | S14: 0.010923026 | T14: 9 | V14: =V75*(H14-S14) -> 72239924 | W14: =W75*(G14-R14) -> 5.4492887e+08 | X14: =N14*$J14*$P14 -> 2.3189152e+09 | Y14: =O14*$J14*$P14 -> 9.3124527e+08 | Z14: =I14*P14 -> 2.1650283e+10 | AA14: =- V14*COS(Q14*PI()/180) + W14*SIN(Q14*PI()/180) -> -1.8530316e+08 | AB14: =V14*SIN($Q14*PI()/180) + W14*COS($Q14*PI()/180) -> 5.175218e+08 | AC14: =$I14*K14 -> 2.6890673e+10 | AD14: =$I14*L14 -> 5.0181438e+10 | AE14: =J14*M14 -> 8.0753589e+09 | AF14: 0 | AG14: =$Z14*(R14-R14) -> 0 | AH14: =$Z14*(S14-S14) -> 0 | AJ14: 17.576917 | AK14: 1050.5803 | AL14: 0.11848604 | AM14: 0.022979524 | AN14: 0.95109579 | AO14: 1.6822735 | AP14: -12.148812 | AQ14: 0.22787449 | AR14: 0.010923026 | AS14: 2.2867203e+09 | AT14: 2.0890038e+08 | AU14: 0 | AV14: 0 | AW14: 0 | AX14: -2.3221615e+08 | AY14: 9.6344015e+08 | AZ14: 0 | BA14: 0 | BB14: 0 | BC14: 5.0916623e+08 | BD14: 2.26589e+10 | BE14: 2.2983707e-07 | BF14: -9.2604417e-07 | BG14: 0 | BH14: 2.6890673e+10 | BI14: 0.24626657 | BJ14: 0 | BK14: 5.0181438e+10 | BL14: 0 | BM14: 8.3968184e+09
A15: 23.43589 | B15: 668.16759 | C15: 0.1325207 | D15: 0.029877098 | E15: 0.84089545 | F15: 1.6630133 | G15: 0.99647378 | H15: 0.061322628 | I15: 2.0627464e+10 | J15: 2.0389726e+09 | K15: 1.0184901 | L15: 1.7319464 | M15: 1.3531493 | N15: 0.48898323 | O15: 0.22937211 | P15: 0.97074181 | Q15: -13.15361 | R15: 0.45997933 | S15: 0.015249504 | T15: 10 | V15: =V76*(H15-S15) -> 44465779 | W15: =W76*(G15-R15) -> 2.4503794e+08 | X15: =N15*$J15*$P15 -> 9.678523e+08 | Y15: =O15*$J15*$P15 -> 4.5399988e+08 | Z15: =I15*P15 -> 2.0023942e+10 | AA15: =- V15*COS(Q15*PI()/180) + W15*SIN(Q15*PI()/180) -> -99060605 | AB15: =V15*SIN($Q15*PI()/180) + W15*COS($Q15*PI()/180) -> 2.2849025e+08 | AC15: =$I15*K15 -> 2.1008868e+10 | AD15: =$I15*L15 -> 3.5725662e+10 | AE15: =J15*M15 -> 2.7590343e+09 | AF15: 0 | AG15: =$Z15*(R15-R15) -> 0 | AH15: =$Z15*(S15-S15) -> 0 | AJ15: 23.43589 | AK15: 668.16759 | AL15: 0.1325207 | AM15: 0.029877098 | AN15: 0.84089545 | AO15: 1.6630133 | AP15: -13.15361 | AQ15: 0.45997933 | AR15: 0.015249504 | AS15: 9.5922703e+08 | AT15: 66013025 | AU15: 0 | AV15: 0 | AW15: 0 | AX15: -1.2634898e+08 | AY15: 4.6262515e+08 | AZ15: 0 | BA15: 0 | BB15: 0 | BC15: 2.2581273e+08 | BD15: 2.043079e+10 | BE15: 0 | BF15: 0 | BG15: 0 | BH15: 2.1008868e+10 | BI15: -0.00078043474 | BJ15: 0 | BK15: 3.5725662e+10 | BL15: 0 | BM15: 2.8957296e+09
A16: 29.294862 | B16: 530.9955 | C16: 0.12241835 | D16: 0.034538377 | E16: 0.70879916 | F16: 1.6437341 | G16: 1.1424782 | H16: 0.068895423 | I16: 2.4446843e+10 | J16: 1.9266794e+09 | K16: 0.63341055 | L16: 1.2862599 | M16: 0.52830648 | N16: 0.29857549 | O16: 0.17316622 | P16: 0.83766198 | Q16: -4.909548 | R16: 0.56604333 | S16: 0.017980336 | T16: 11 | V16: =V77*(H16-S16) -> 24526931 | W16: =W77*(G16-R16) -> 1.6118535e+08 | X16: =N16*$J16*$P16 -> 4.818728e+08 | Y16: =O16*$J16*$P16 -> 2.7947402e+08 | Z16: =I16*P16 -> 2.0478191e+10 | AA16: =- V16*COS(Q16*PI()/180) + W16*SIN(Q16*PI()/180) -> -38231662 | AB16: =V16*SIN($Q16*PI()/180) + W16*COS($Q16*PI()/180) -> 1.5849488e+08 | AC16: =$I16*K16 -> 1.5484889e+10 | AD16: =$I16*L16 -> 3.1444995e+10 | AE16: =J16*M16 -> 1.0178772e+09 | AF16: 0 | AG16: =$Z16*(R16-R16) -> 0 | AH16: =$Z16*(S16-S16) -> 0 | AJ16: 29.294862 | AK16: 530.9955 | AL16: 0.12241835 | AM16: 0.034538377 | AN16: 0.70879916 | AO16: 1.6437341 | AP16: -4.909548 | AQ16: 0.56604333 | AR16: 0.017980336 | AS16: 4.8185624e+08 | AT16: -1830605.4 | AU16: 0 | AV16: 0 | AW16: 0 | AX16: -49258531 | AY16: 2.7949058e+08 | AZ16: 0 | BA16: 0 | BB16: 0 | BC16: 1.5948233e+08 | BD16: 2.0472143e+10 | BE16: 5.9385958e-08 | BF16: 5.1011418e-09 | BG16: 0 | BH16: 1.5484889e+10 | BI16: 0.0027511445 | BJ16: 0 | BK16: 3.1444995e+10 | BL16: 0 | BM16: 1.113705e+09
A17: 35.153835 | B17: 483.98493 | C17: 0.11952283 | D17: 0.031485917 | E17: 0.64792493 | F17: 1.5640176 | G17: 1.1071872 | H17: 0.076334026 | I17: 2.91801e+10 | J17: 2.0610158e+09 | K17: 0.45725295 | L17: 0.95396475 | M17: 0.3021623 | N17: 0.22741959 | O17: 0.1471278 | P17: 0.7404089 | Q17: -1.8974687 | R17: 0.61827407 | S17: 0.016299095 | T17: 12 | V17: =V78*(H17-S17) -> 20833766 | W17: =W78*(G17-R17) -> 1.0977558e+08 | X17: =N17*$J17*$P17 -> 3.4704102e+08 | Y17: =O17*$J17*$P17 -> 2.245162e+08 | Z17: =I17*P17 -> 2.1605205e+10 | AA17: =- V17*COS(Q17*PI()/180) + W17*SIN(Q17*PI()/180) -> -24457124 | AB17: =V17*SIN($Q17*PI()/180) + W17*COS($Q17*PI()/180) -> 1.0902556e+08 | AC17: =$I17*K17 -> 1.3342687e+10 | AD17: =$I17*L17 -> 2.7836787e+10 | AE17: =J17*M17 -> 6.2276126e+08 | AF17: 0 | AG17: =$Z17*(R17-R17) -> 0 | AH17: =$Z17*(S17-S17) -> 0 | AJ17: 35.153835 | AK17: 483.98493 | AL17: 0.11952283 | AM17: 0.031485917 | AN17: 0.64792493 | AO17: 1.5640176 | AP17: -1.8974687 | AQ17: 0.61827407 | AR17: 0.016299095 | AS17: 3.4704092e+08 | AT17: -112440.28 | AU17: 0 | AV17: 0 | AW17: 0 | AX17: -26495916 | AY17: 2.245163e+08 | AZ17: 0 | BA17: 0 | BB17: 0 | BC17: 1.0927106e+08 | BD17: 2.1366359e+10 | BE17: 0 | BF17: 0 | BG17: 0 | BH17: 1.3342687e+10 | BI17: 0.00037919804 | BJ17: 0 | BK17: 2.7836787e+10 | BL17: 0 | BM17: 6.7795755e+08
... A31: 117.17945 | B31: 5.4094111 | C31: 0.045013052 | D31: 0.00678579 | E31: 0.036589114 | F31: 0.12872356 | G31: 0.18272155 | H31: 0.0057927533 | I31: 2.4018099e+10 | J31: 3.901695e+09 | K31: 7.8722274e-06 | L31: 5.7631715e-05 | M31: 1.5921308e-05 | N31: 0.7634796 | O31: 0.045931347 | P31: 0.0053418617 | Q31: -0.85254664 | R31: 0.064477171 | S31: 0.0066633888 | T31: 26 | V31: =V92*(H31-S31) -> -13853.853 | W31: =W92*(G31-R31) -> 113236.86 | X31: =N31*$J31*$P31 -> 15912682 | Y31: =O31*$J31*$P31 -> 957315.6 | Z31: =I31*P31 -> 1.2830136e+08 | AA31: =- V31*COS(Q31*PI()/180) + W31*SIN(Q31*PI()/180) -> 12167.446 | AB31: =V31*SIN($Q31*PI()/180) + W31*COS($Q31*PI()/180) -> 113430.46 | AC31: =$I31*K31 -> 189075.93 | AD31: =$I31*L31 -> 1384204.2 | AE31: =J31*M31 -> 62120.088 | AF31: 0 | AG31: =$Z31*(R31-R31) -> 0 | AH31: =$Z31*(S31-S31) -> 0 | AJ31: 117.17945 | AK31: 5.4094111 | AL31: 0.045013052 | AM31: 0.00678579 | AN31: 0.036589114 | AO31: 0.12872356 | AP31: -0.85254664 | AQ31: 0.064477171 | AR31: 0.0066633888 | AS31: 15912682 | AT31: 107.67626 | AU31: 0 | AV31: 0 | AW31: 0 | AX31: -14131.134 | AY31: 957315.6 | AZ31: 0 | BA31: 0 | BB31: 0 | BC31: 113196.97 | BD31: 1.1865913e+08 | BE31: 1.3857332e-11 | BF31: -9.3121948e-10 | BG31: 0 | BH31: 189075.93 | BI31: 7.7431214e-09 | BJ31: 0 | BK31: 1384204.2 | BL31: 0 | BM31: 75517.538
E34: Trial & Error
E35: PROCESS
M36: direct method | Q36: GA_use
E37: =A5 -> r_[m] | G37: polar_inertia | H37: K_[m4/rad] | J37: X_new (sh-e off) | K37: Y_new (sh-e off) | M37: GAxX_[Nm] | N37: - GAxX_[Nm] | O37: GAyY_[Nm] | Q37: GAxX_alter_[Nm] | R37: - GAxX_alter_[Nm] | S37: GAyY_alter_[Nm]
E38: =A6 -> 0 | G38: =K6+L6 -> 15.843497 | H38: =M6 -> 22.331655 | J38: =($G6-$R6)*COS($Q6*PI()/180) + ($H6-$S6)*SIN($Q6*PI()/180) -> -0.0023393733 | K38: =- ($G6-$R6)*SIN($Q6*PI()/180)+($H6-$S6)*COS($Q6*PI()/180) -> 0.0059811533 | M38: =X6*K38 -> 40232700 | N38: =-M38 -> -40232700 | O38: =Y6*J38 -> -15765286 | Q38: =$J6*$P6*K38 -> 56337000 | R38: =-Q38 -> -56337000 | S38: =$J6*$P6*J38 -> -22034759
E39: =A7 -> 1.1717945 | G39: =K7+L7 -> 15.345286 | H39: =M7 -> 21.654596 | J39: =($G7-$R7)*COS($Q7*PI()/180) + ($H7-$S7)*SIN($Q7*PI()/180) -> -0.000777318 | K39: =- ($G7-$R7)*SIN($Q7*PI()/180)+($H7-$S7)*COS($Q7*PI()/180) -> 0.0029056743 | M39: =X7*K39 -> 18558753 | N39: =-M39 -> -18558753 | O39: =Y7*J39 -> -4960770.9 | Q39: =$J7*$P7*K39 -> 25937238 | R39: =-Q39 -> -25937238 | S39: =$J7*$P7*J39 -> -6938658.6
E40: =A8 -> 2.343589 | G40: =K8+L8 -> 14.84595 | H40: =M8 -> 20.934016 | J40: =($G8-$R8)*COS($Q8*PI()/180) + ($H8-$S8)*SIN($Q8*PI()/180) -> -0.00027007338 | K40: =- ($G8-$R8)*SIN($Q8*PI()/180)+($H8-$S8)*COS($Q8*PI()/180) -> -1.0832681e-05 | M40: =X8*K40 -> -65624.776 | N40: =-M40 -> 65624.776 | O40: =Y8*J40 -> -1626530.5 | Q40: =$J8*$P8*K40 -> -91489.556 | R40: =-Q40 -> 91489.556 | S40: =$J8*$P8*J40 -> -2280958.3
E41: =A9 -> 3.5153835 | G41: =K9+L9 -> 13.471527 | H41: =M9 -> 18.90384 | J41: =($G9-$R9)*COS($Q9*PI()/180) + ($H9-$S9)*SIN($Q9*PI()/180) -> 0.00079917693 | K41: =- ($G9-$R9)*SIN($Q9*PI()/180)+($H9-$S9)*COS($Q9*PI()/180) -> 0.00014338201 | M41: =X9*K41 -> 825571.01 | N41: =-M41 -> -825571.01 | O41: =Y9*J41 -> 4314485.7 | Q41: =$J9*$P9*K41 -> 1143751.6 | R41: =-Q41 -> -1143751.6 | S41: =$J9*$P9*J41 -> 6374997.3
E42: =A10 -> 4.6871779 | G42: =K10+L10 -> 12.157449 | H42: =M10 -> 16.919384 | J42: =($G10-$R10)*COS($Q10*PI()/180) + ($H10-$S10)*SIN($Q10*PI()/180) -> 0.0055611525 | K42: =- ($G10-$R10)*SIN($Q10*PI()/180)+($H10-$S10)*COS($Q10*PI()/180) -> 0.0012126223 | M42: =X10*K42 -> 6631140.3 | N42: =-M42 -> -6631140.3 | O42: =Y10*J42 -> 26690124 | Q42: =$J10*$P10*K42 -> 9093417.5 | R42: =-Q42 -> -9093417.5 | S42: =$J10*$P10*J42 -> 41702912
E43: =A11 -> 5.8589724 | G43: =K11+L11 -> 11.051553 | H43: =M11 -> 15.154369 | J43: =($G11-$R11)*COS($Q11*PI()/180) + ($H11-$S11)*SIN($Q11*PI()/180) -> 0.014778351 | K43: =- ($G11-$R11)*SIN($Q11*PI()/180)+($H11-$S11)*COS($Q11*PI()/180) -> 0.0036387901 | M43: =X11*K43 -> 18905295 | N43: =-M43 -> -18905295 | O43: =Y11*J43 -> 62725959 | Q43: =$J11*$P11*K43 -> 25592055 | R43: =-Q43 -> -25592055 | S43: =$J11*$P11*J43 -> 1.0393794e+08
E44: =A12 -> 8.7884587 | G44: =K12+L12 -> 9.1181486 | H44: =M12 -> 11.738782 | J44: =($G12-$R12)*COS($Q12*PI()/180) + ($H12-$S12)*SIN($Q12*PI()/180) -> 0.060918878 | K44: =- ($G12-$R12)*SIN($Q12*PI()/180)+($H12-$S12)*COS($Q12*PI()/180) -> 0.021116472 | M44: =X12*K44 -> 96110546 | N44: =-M44 -> -96110546 | O44: =Y12*J44 -> 1.8364468e+08 | Q44: =$J12*$P12*K44 -> 1.2771989e+08 | R44: =-Q44 -> -1.2771989e+08 | S44: =$J12*$P12*J44 -> 3.684589e+08
E45: =A13 -> 11.717945 | G45: =K13+L13 -> 7.9601961 | H45: =M13 -> 8.5590491 | J45: =($G13-$R13)*COS($Q13*PI()/180) + ($H13-$S13)*SIN($Q13*PI()/180) -> 0.19633876 | K45: =- ($G13-$R13)*SIN($Q13*PI()/180)+($H13-$S13)*COS($Q13*PI()/180) -> 0.066273583 | M45: =X13*K45 -> 2.6461266e+08 | N45: =-M45 -> -2.6461266e+08 | O45: =Y13*J45 -> 4.7345408e+08 | Q45: =$J13*$P13*K45 -> 3.4037332e+08 | R45: =-Q45 -> -3.4037332e+08 | S45: =$J13*$P13*J45 -> 1.0083728e+09
E46: =A14 -> 17.576917 | G46: =K14+L14 -> 4.42068 | H46: =M14 -> 3.1069015 | J46: =($G14-$R14)*COS($Q14*PI()/180) + ($H14-$S14)*SIN($Q14*PI()/180) -> 0.56163126 | K46: =- ($G14-$R14)*SIN($Q14*PI()/180)+($H14-$S14)*COS($Q14*PI()/180) -> 0.15285697 | M46: =X14*K46 -> 3.5446234e+08 | N46: =-M46 -> -3.5446234e+08 | O46: =Y14*J46 -> 5.2301646e+08 | Q46: =$J14*$P14*K46 -> 4.9337256e+08 | R46: =-Q46 -> -4.9337256e+08 | S46: =$J14*$P14*J46 -> 1.812763e+09
E47: =A15 -> 23.43589 | G47: =K15+L15 -> 2.7504365 | H47: =M15 -> 1.3531493 | J47: =($G15-$R15)*COS($Q15*PI()/180) + ($H15-$S15)*SIN($Q15*PI()/180) -> 0.51193418 | K47: =- ($G15-$R15)*SIN($Q15*PI()/180)+($H15-$S15)*COS($Q15*PI()/180) -> 0.16695036 | M47: =X15*K47 -> 1.6158329e+08 | N47: =-M47 -> -1.6158329e+08 | O47: =Y15*J47 -> 2.3241806e+08 | Q47: =$J15*$P15*K47 -> 3.3044751e+08 | R47: =-Q47 -> -3.3044751e+08 | S47: =$J15*$P15*J47 -> 1.0132795e+09
E48: =A16 -> 29.294862 | G48: =K16+L16 -> 1.9196705 | H48: =M16 -> 0.52830648 | J48: =($G16-$R16)*COS($Q16*PI()/180) + ($H16-$S16)*SIN($Q16*PI()/180) -> 0.56996253 | K48: =- ($G16-$R16)*SIN($Q16*PI()/180)+($H16-$S16)*COS($Q16*PI()/180) -> 0.10006129 | M48: =X16*K48 -> 48216812 | N48: =-M48 -> -48216812 | O48: =Y16*J48 -> 1.5928972e+08 | Q48: =$J16*$P16*K48 -> 1.6148952e+08 | R48: =-Q48 -> -1.6148952e+08 | S48: =$J16*$P16*J48 -> 9.1986598e+08
E49: =A17 -> 35.153835 | G49: =K17+L17 -> 1.4112177 | H49: =M17 -> 0.3021623 | J49: =($G17-$R17)*COS($Q17*PI()/180) + ($H17-$S17)*SIN($Q17*PI()/180) -> 0.48665728 | K49: =- ($G17-$R17)*SIN($Q17*PI()/180)+($H17-$S17)*COS($Q17*PI()/180) -> 0.076190428 | M49: =X17*K49 -> 26441204 | N49: =-M49 -> -26441204 | O49: =Y17*J49 -> 1.0926244e+08 | Q49: =$J17*$P17*K49 -> 1.1626617e+08 | R49: =-Q49 -> -1.1626617e+08 | S49: =$J17*$P17*J49 -> 7.4263628e+08
... E63: =A31 -> 117.17945 | G63: =K31+L31 -> 6.5503943e-05 | H63: =M31 -> 1.5921308e-05 | J63: =($G31-$R31)*COS($Q31*PI()/180) + ($H31-$S31)*SIN($Q31*PI()/180) -> 0.11824425 | K63: =- ($G31-$R31)*SIN($Q31*PI()/180)+($H31-$S31)*COS($Q31*PI()/180) -> 0.00088884233 | M63: =X31*K63 -> 14143.866 | N63: =-M63 -> -14143.866 | O63: =Y31*J63 -> 113197.06 | Q63: =$J31*$P31*K63 -> 18525.532 | R63: =-Q63 -> -18525.532 | S63: =$J31*$P31*J63 -> 2464483.8
V66: c2_GAx | W66: c2_GAy
V67: =0.5*($X6+$Y6) + 0.5*($X6-$Y6)*COS(-2*$Q6/180) -> 6.7265928e+09 | W67: =0.5*($X6+$Y6) - 0.5*($X6-$Y6)*COS(-2*$Q6/180) -> 6.7390926e+09
V68: =0.5*($X7+$Y7) + 0.5*($X7-$Y7)*COS(-2*$Q7/180) -> 6.3870488e+09 | W68: =0.5*($X7+$Y7) - 0.5*($X7-$Y7)*COS(-2*$Q7/180) -> 6.3819305e+09
V69: =0.5*($X8+$Y8) + 0.5*($X8-$Y8)*COS(-2*$Q8/180) -> 6.0578108e+09 | W69: =0.5*($X8+$Y8) - 0.5*($X8-$Y8)*COS(-2*$Q8/180) -> 6.0227757e+09
V70: =0.5*($X9+$Y9) + 0.5*($X9-$Y9)*COS(-2*$Q9/180) -> 5.7541543e+09 | W70: =0.5*($X9+$Y9) - 0.5*($X9-$Y9)*COS(-2*$Q9/180) -> 5.4023495e+09
...

Sheet HAWC2_2_hGAST_noFPM
A1: IEA-15-240-RWT | K1: HAWC2 | P1: HAWC2 | W1: HAWC2 | AK1: HAWC_2 | BF1: HAWC2 | BN1: hGAST | CE1: HAWC2 | DA1: hGAST | DI1: hGAST | EJ1: HAWC2 | EO1: hGAST | FH1: hGAST | FM1: hGAST
A2: File Name: | B2: https://github.com/IEAWindSystems/IEA-15-240-RWT/tree/master/Documentation | K2: File Name: | L2: https://github.com/IEAWindSystems/IEA-15-240-RWT/blob/master/HAWC2/IEA-15-240-RWT/IEA_15MW_RWT_ae.dat | P2: File Name: | Q2: https://github.com/IEAWindSystems/IEA-15-240-RWT/blob/master/HAWC2/IEA-15-240-RWT/IEA_15MW_RWT_WTG_bodies_noFPM.htc | W2: Details: | X2: PROCESS | AK2: File Name: | AL2: https://github.com/IEAWindSystems/IEA-15-240-RWT/blob/master/HAWC2/IEA-15-240-RWT/IEA_15MW_RWT_Blade_st_noFPM.st | BN2: Details: | BO2: PROCESS | BP2: reference = pitch axis | BV2: Express in BLADE | BW2: FIXED COO | BX2: negative twist angle about y axis - traditional notation | CE2: PROCESS | CF2: intermediate steps for final hGAST data | CL2: Process description report | CN2: github | CO2: notebook | CU2: Apply Steiner? | CV2: 1 | CW2: 1=yes / 0=no | DA2: Method 1 | DI2: Express in BLADE | DJ2: FIXED COO | DK2: Details: | DL2: PROCESS | DM2: processed data to be used as input in machi.inp (in span stations of HAWC2) | DS2: no_FPM | DZ2: Method 1 | EJ2: Method 2 | EO2: Method 2 | FH2: Direct method | FM2: Details: | FN2: Interpolated properties @ user-determined radial (R) stations, to be used as input in machi.inp of hGAST | FX2: format:
A3: Details: | B3: RAW | C3: DATA | D3: Profile of blade geometry ("Blade Geometry" sheet in excel file | H3: IEA_blade_geo; | K3: Details: | L3: RAW | M3: DATA | N3: ae.dat; | P3: Details: | Q3: RAW | R3: DATA | S3: c2_def; | U3: process | W3: Notes: | Y3: directions | AK3: Details: | AL3: RAW | AM3: DATA | AN3: Structural properties for blade model: standard Timoshenko beam | BF3: Details: | BG3: PROCESS | BH3: reference = pitch axis | BN3: Notes: | BO3: Local Pitch Axis coo | BV3: 1 | BW3: 1=yes / 0=no | BX3: Blade Fixed Pitch Axis coo | CE3: @ principal bending axes --- local coo | CL3: @ ea, axes parallel to local c2_def axes | CU3: Steiner theorem @ pitch axis --- local pitch axis coo | DA3: @ pitch axis --- local pitch axis coo | DD3: @ pitch axis --- local pitch axis coo | DI3: =$BV$3 -> 1 | DJ3: check BV3 1=yes / 0=no | DK3: Notes: | DQ3: Blade fixed pitch axis coo | DW3: Blade fixed pitch axis coo | EC3: Blade fixed pitch axis coo | EJ3: @ pitch axis --- local pitch axis coo | EO3: Details: | EP3: Method 2 for calculating and rotating structural properties | ET3: * 1st, the rotation of HAWC2 x-y axes is performed | EX3: * 2nd, the transformed system if mapped to hGAST coordinate system | FH3: @ pitch axis --- Blade fixed coo | FM3: Notes: | FO3: PROCESS | FR3: Interpolation | FX3: iread = | FY3: 0
A4: Spanwise position [r/R] | B4: Chord [m] | C4: Twist [rad] | D4: Twist [deg] | E4: Pitch axis [x/c] | F4: Span [m] | G4: Prebend [m] | H4: Sweep [m] | I4: #53 | K4: r [m] | L4: c [m] | M4: t/c [%] | N4: $30 | P4: x_c2 [m] | Q4: y_c2 [m] | R4: z_c2 [m] | S4: θt_c2 [deg] | T4: $ 34 | U4: r_c2 [m] | W4: LOOKUP | X4: c2_def | Y4: chord/edge | Z4: flap/prebend | AA4: span | AB4: twist | AD4: LOOKUP | AE4: ae.dat | AF4: chord | AG4: LOOKUP | AH4: IEA_blade_geo | AI4: x/c | BE4: check | BF4: Notes: | BG4: Local Pitch Axis coo | BN4: half chord | BO4: cm_chord | BP4: cm_thick | BQ4: sh_chord | BR4: sh_thick | BS4: e_chord | BT4: e_thick | BV4: twist | BW4: twist | BX4: cm_edg | BY4: cm_flp | BZ4: sh_edg | CA4: sh_flp | CB4: e_edg | CC4: e_flp | CE4: Details: | CJ4: shear_x | CK4: shear_y | CL4: chord | CM4: thickness | CN4: cross | CO4: flap | CP4: edge | CQ4: flap-edge | CR4: shear_x | CS4: shear_y | CT4: cross | CU4: chord | CV4: thickness | CW4: cross | CX4: flap | CY4: edge | CZ4: flap-edge | DA4: sign change for cross products | DD4: coupling terms | DI4: twist | DJ4: twist | DL4: curve | DM4: span | DN4: sweep | DO4: prebend | DP4: linear mass | DQ4: cg_edge | DR4: cg_flap | DS4: flap | DT4: edge | DU4: flap-edge | DV4: tension | DW4: tension - flap | DX4: tension - edge | DY4: flap | DZ4: edge | EA4: flap-edge | EB4: torsion | EC4: shear chord | ED4: shear thickness | EF4: torsion - shear thick | EG4: torsion - shear chord | EH4: diameter | EJ4: coupling terms | EO4: both | EP4: both | EQ4: HAWC2 | ER4: hGAST | ES4: both | ET4: HAWC2 | EU4: hGAST | EV4: both | EW4: both | EX4: HAWC2 | EY4: hGAST | EZ4: both | FA4: both | FB4: HAWC2 | FC4: hGAST | FD4: both | FE4: HAWC2 | FF4: hGAST | FH4: coupling terms | FM4: LOOKUP | FN4: machi | FQ4: RAW
A5: 0 | B5: 5.2 | C5: 0.2721763 | D5: =C5*180/PI() -> 15.594553 | E5: 0.50454545 | F5: 0 | G5: 0 | H5: 0 | I5: 1 | K5: 0 | L5: 5.2 | M5: 100 | N5: 1 | P5: 0.0227663 | Q5: -0.00635412 | R5: 0 | S5: -15.5946 | T5: 1 | U5: 0 | W5: pre | X5: next | Y5: x_[m] | Z5: y_[m] | AA5: z_[m] | AB5: θt_[deg] | AD5: pre | AE5: next | AF5: c_ [m] | AG5: pre | AH5: next | AI5: pitch_axis_[%] | AK5: r_[m] | AL5: m_[kg/m] | AM5: x_cg_[m] | AN5: y_cg_[m] | AO5: ri_x_[m] | AP5: ri_y_[m] | AQ5: x_sh_[m] | AR5: y_sh_[m] | AS5: E_[N/m^2] | AT5: G_[N/m^2] | AU5: I_x_[m^4] | AV5: I_y_[m^4] | AW5: I_p_[m^4] | AX5: k_x_[-] | AY5: k_y_[-] | AZ5: A_[m^2] | BA5: pitch_[deg] | BB5: x_e_[m] | BC5: y_e_[m] | BD5: $26 | BE5: x_c/2_[m] | BF5: x_c/2_[m] | BG5: x_cg_[m] | BH5: y_cg_[m] | BI5: x_sh_[m] | BJ5: y_sh_[m] | BK5: x_e_[m] | BL5: y_e_[m] | BN5: x_c/2_[m] | BO5: x_cg_[m] | BP5: z_cg_[m] | BQ5: x_sh_[m] | BR5: z_sh_[m] | BS5: x_e_[m] | BT5: z_e_[m] | BV5: θ_t [deg] | BW5: θ_t [rad] | BX5: x_cg_[m] | BY5: z_cg_[m] | BZ5: x_sh_[m] | CA5: z_sh_[m] | CB5: x_e_[m] | CC5: z_e_[m] | CE5: pri_ρIxx [kg*m] | CF5: pri_ρIyy [kg*m] | CG5: pri_EIxx [N*m^2] | CH5: pri_EIyy [N*m^2] | CI5: GJ [N*m^2] | CJ5: pri_GAx [N] | CK5: pri_GAy [N] | CL5: c2_ρΙxx | CM5: c2_ρΙyy | CN5: c2_ρΙxy | CO5: c2_EΙxx | CP5: c2_EΙyy | CQ5: c2_EΙxy | CR5: c2_GAx [N] | CS5: c2_GAy [N] | CT5: c2_GAxy [N] | CU5: st_ρΙxx | CV5: st_ρΙyy | CW5: st_ρΙxy | CX5: st_EΙxx | CY5: st_EΙyy | CZ5: st_EΙxy | DA5: st_ρΙxz | DB5: st_EIxz | DC5: GAxz | DD5: pa_EAx | DE5: pa_EAz | DF5: pa_GAxX | DG5: pa_GAzZ | DI5: rotate by - θ_t [deg] | DJ5: - θ_t [rad] | DK5: **num | DL5: R [curv] | DM5: Y [span] | DN5: X [swe] | DO5: Z [ben] | DP5: m [kg/m] | DQ5: x_cg [m] | DR5: z_cg [m] | DS5: ρIxx [kg*m] | DT5: ρIzz [kg*m] | DU5: ρIxz [kg*m] | DV5: EA [N] | DW5: + EAx [Nm] | DX5: EAz [Nm] | DY5: Eixx [Nm^2] | DZ5: Eizz [Nm^2] | EA5: + Eixz [Nm^2] | EB5: Git [Nm^2] | EC5: GxA [N] | ED5: GzA [N] | EE5: GxzA [N] | EF5: GxAX [Nm] | EG5: + GzAZ [Nm] | EH5: D [m] | EJ5: pa_EAx | EK5: pa_EAy | EL5: pa_GAxX | EM5: pa_GAyY | EO5: ρIxx [kg*m] | EP5: ρIyy,zz [kg*m] | EQ5: ρIxy [kg*m] | ER5: ρIxz [kg*m] | ES5: + EAx [Nm] | ET5: EAy [Nm] | EU5: EAz [Nm] | EV5: EIxx [Nm^2] | EW5: EIyy,zz [Nm^2] | EX5: + EIxy [Nm^2] | EY5: + EIxz [Nm^2] | EZ5: GxA [N] | FA5: Gy,zA [N] | FB5: GxyA [N] | FC5: GxzA [N] | FD5: GxAX [Nm] | FE5: + GyAY [Nm] | FF5: + GzAZ [Nm] | FH5: EAx | FI5: EAz | FJ5: GAxX | FK5: GAzZ | FM5: pre | FN5: next | FP5: **num | FQ5: Y [span] | FR5: X [swe] | FS5: Z [ben] | FT5: m [kg/m] | FU5: x_cg [m] | FV5: z_cg [m] | FW5: ρIxx [kg*m] | FX5: ρIzz [kg*m] | FY5: ρIxz [kg*m] | FZ5: EA [N] | GA5: + EAx [Nm] | GB5: EAz [Nm] | GC5: Eixx [Nm^2] | GD5: Eizz [Nm^2] | GE5: + Eixz [Nm^2] | GF5: Git [Nm^2] | GG5: GxA [N] | GH5: GzA [N] | GI5: GxAX [Nm] | GJ5: + GzAZ [Nm] | GK5: D [m]
A6: 0.020408163 | B6: 5.2088399 | C6: 0.27205736 | D6: =C6*180/PI() -> 15.587739 | E6: 0.49001868 | F6: 2.3877551 | G6: -0.018400065 | H6: 0 | I6: 2 | K6: 4.1284356 | L6: 5.2269516 | M6: 98.341624 | N6: 2 | P6: -0.01293848 | Q6: 0.01261945 | R6: 1.171132 | S6: -15.59122 | T6: 2 | U6: =SQRT( (P6-P5)^2 + (Q6-Q5)^2 + (R6-R5)^2 ) + U5 -> 1.1718298 | W6: =_xlfn.XLOOKUP(AK6, $U$5:$U$200, $T$5:$T$200, ,-1) -> 1 | X6: =W6+1 -> 2 | Y6: =_xlfn.LET( _xlpm.r, $AK6, _xlpm.rp, _xlfn.XLOOKUP($W6, $T$5:$T$200, $U$5:$U$200, , -1), _xlpm.rn, _xlfn.XLOOKUP($X6, $T$5:$T$200, $U$5:$U$200, , -1), _xlpm.xp, _xlfn.XLOOKUP($W6, $T$5:$T$200, P$5:P$200, , -1), _xlpm.xn, _xlfn.XLOOKUP($X6, $T$5:$T$200, P$5:P$200, , -1), (_xlpm.r - _xlpm.rp)/(_xlpm.rn - _xlpm.rp)*(_xlpm.xn - _xlpm.xp) + _xlpm.xp ) -> 0.0227663 | Z6: =_xlfn.LET( _xlpm.r, $AK6, _xlpm.rp, _xlfn.XLOOKUP($W6, $T$5:$T$200, $U$5:$U$200, , -1), _xlpm.rn, _xlfn.XLOOKUP($X6, $T$5:$T$200, $U$5:$U$200, , -1), _xlpm.xp, _xlfn.XLOOKUP($W6, $T$5:$T$200, Q$5:Q$200, , -1), _xlpm.xn, _xlfn.XLOOKUP($X6, $T$5:$T$200, Q$5:Q$200, , -1), (_xlpm.r - _xlpm.rp)/(_xlpm.rn - _xlpm.rp)*(_xlpm.xn - _xlpm.xp) + _xlpm.xp ) -> -0.00635412 | AA6: =_xlfn.LET( _xlpm.r, $AK6, _xlpm.rp, _xlfn.XLOOKUP($W6, $T$5:$T$200, $U$5:$U$200, , -1), _xlpm.rn, _xlfn.XLOOKUP($X6, $T$5:$T$200, $U$5:$U$200, , -1), _xlpm.xp, _xlfn.XLOOKUP($W6, $T$5:$T$200, R$5:R$200, , -1), _xlpm.xn, _xlfn.XLOOKUP($X6, $T$5:$T$200, R$5:R$200, , -1), (_xlpm.r - _xlpm.rp)/(_xlpm.rn - _xlpm.rp)*(_xlpm.xn - _xlpm.xp) + _xlpm.xp ) -> 0 | AB6: =_xlfn.LET( _xlpm.r, $AK6, _xlpm.rp, _xlfn.XLOOKUP($W6, $T$5:$T$200, $U$5:$U$200, , -1), _xlpm.rn, _xlfn.XLOOKUP($X6, $T$5:$T$200, $U$5:$U$200, , -1), _xlpm.xp, _xlfn.XLOOKUP($W6, $T$5:$T$200, S$5:S$200, , -1), _xlpm.xn, _xlfn.XLOOKUP($X6, $T$5:$T$200, S$5:S$200, , -1), (_xlpm.r - _xlpm.rp)/(_xlpm.rn - _xlpm.rp)*(_xlpm.xn - _xlpm.xp) + _xlpm.xp ) -> -15.5946 | AD6: =_xlfn.XLOOKUP(AK6, $K$5:$K$200, $N$5:$N$200, ,-1) -> 1 | AE6: =AD6+1 -> 2 | AF6: =_xlfn.LET( _xlpm.r, $AK6, _xlpm.rp, _xlfn.XLOOKUP($AD6, $N$5:$N$200, $K$5:$K$200, , -1), _xlpm.rn, _xlfn.XLOOKUP($AE6, $N$5:$N$200, $K$5:$K$200, , -1), _xlpm.xp, _xlfn.XLOOKUP($AD6, $N$5:$N$200, L$5:L$200, , -1), _xlpm.xn, _xlfn.XLOOKUP($AE6, $N$5:$N$200, L$5:L$200, , -1), (_xlpm.r - _xlpm.rp)/(_xlpm.rn - _xlpm.rp)*(_xlpm.xn - _xlpm.xp) + _xlpm.xp ) -> 5.2 | AG6: =_xlfn.XLOOKUP(AA6, $F$5:$F$200, $I$5:$I$200, ,-1) -> 1 | AH6: =AG6+1 -> 2 | AI6: =_xlfn.LET( _xlpm.r, $AA6, _xlpm.rp, _xlfn.XLOOKUP($AG6, $I$5:$I$200, $F$5:$F$200, , -1), _xlpm.rn, _xlfn.XLOOKUP($AH6, $I$5:$I$200, $F$5:$F$200, , -1), _xlpm.xp, _xlfn.XLOOKUP($AG6, $I$5:$I$200, E$5:E$200, , -1), _xlpm.xn, _xlfn.XLOOKUP($AH6, $I$5:$I$200, E$5:E$200, , -1), (_xlpm.r - _xlpm.rp)/(_xlpm.rn - _xlpm.rp)*(_xlpm.xn - _xlpm.xp) + _xlpm.xp ) -> 0.50454545 | AK6: 0 | AL6: 3126.5244 | AM6: 0.00011619906 | AN6: -0.00014234568 | AO6: 1.8027984 | AP6: 1.8021313 | AQ6: -0.001501774 | AR6: 0.005716245 | AS6: 1.8877163e+10 | AT6: 3.9142658e+09 | AU6: 7.9258187 | AV6: 7.9176781 | AW6: 22.331655 | AX6: 0.71414345 | AY6: 0.71547347 | AZ6: 2.4063482 | BA6: -6.0000871 | BB6: 0.00019957381 | BC6: -0.0004766766 | BD6: 1 | BE6: =AI6*AF6 - AF6/2 -> 0.023636364 | BF6: =Y6 -> 0.0227663 | BG6: =$BF6+AM6 -> 0.022882499 | BH6: =AN6 -> -0.00014234568 | BI6: =$BF6+AQ6 -> 0.021264526 | BJ6: =AR6 -> 0.005716245 | BK6: =$BF6+BB6 -> 0.022965874 | BL6: =BC6 -> -0.0004766766 | BN6: =-BF6 -> -0.0227663 | BO6: =-BG6 -> -0.022882499 | BP6: =BH6 -> -0.00014234568 | BQ6: =-BI6 -> -0.021264526 | BR6: =BJ6 -> 0.005716245 | BS6: =-BK6 -> -0.022965874 | BT6: =BL6 -> -0.0004766766 | BV6: =IF($BV$3=1, - AB6, 0) -> 15.5946 | BW6: =RADIANS(BV6) -> 0.27217712 | BX6: =BO6*COS($BW6) - BP6*SIN($BW6) -> -0.02200188 | BY6: =BO6*SIN($BW6) + BP6*COS($BW6) -> -0.006288586 | BZ6: =BQ6*COS($BW6) - BR6*SIN($BW6) -> -0.022018427 | CA6: =BQ6*SIN($BW6) + BR6*COS($BW6) -> -0.0002107041 | CB6: =BS6*COS($BW6) - BT6*SIN($BW6) -> -0.021992307 | CC6: =BS6*SIN($BW6) + BT6*COS($BW6) -> -0.006633023 | CE6: =AO6^2 * $AL6 -> 10161.461 | CF6: =AP6^2 * $AL6 -> 10153.942 | CG6: =$AS6*AU6 -> 1.4961697e+11 | CH6: =$AS6*AV6 -> 1.494633e+11 | CI6: =AT6*AW6 -> 8.7412032e+10 | CJ6: =$AT6*$AZ6*AX6 -> 6.7265789e+09 | CK6: =$AT6*$AZ6*AY6 -> 6.7391065e+09 | CL6: =0.5*($CE6+$CF6)+0.5*($CE6-$CF6)*COS(-2*$BA6*PI()/180) - 0 -> 10161.379 | CM6: =0.5*($CE6+$CF6)-0.5*($CE6-$CF6)*COS(-2*$BA6*PI()/180) + 0 -> 10154.024 | CN6: =0.5*($CE6-$CF6)*SIN(-2*$BA6*PI()/180) + 0 -> 0.78164695 | CO6: =0.5*($CG6+$CH6)+0.5*($CG6-$CH6)*COS(-2*$BA6*PI()/180) - 0 -> 1.4961529e+11 | CP6: =0.5*($CG6+$CH6)-0.5*($CG6-$CH6)*COS(-2*$BA6*PI()/180) + 0 -> 1.4946498e+11 | CQ6: =0.5*($CG6-$CH6)*SIN(-2*$BA6*PI()/180) + 0 -> 15975329 | CR6: =0.5*($CJ6+$CK6) + 0.5*($CJ6-$CK6)*COS(-2*$BA6*PI()/180) +0 -> 6.7267158e+09 | CS6: =0.5*($CJ6+$CK6) - 0.5*($CJ6-$CK6)*COS(-2*$BA6*PI()/180) -0 -> 6.7389696e+09 | CT6: =- 0.5*($CJ6-$CK6)*SIN(-2*$BA6*PI()/180) + 0 -> 1302331.7 | CU6: =CL6 + $AL6*$BL6^2 * $CV$2 -> 10161.38 | CV6: =CM6 + $AL6*$BK6^2 * $CV$2 -> 10155.674 | CW6: =CN6 + $AL6*$BK6*$BL6 * $CV$2 -> 0.74741996 | CX6: =CO6 + $DV6*$BL6^2 * $CV$2 -> 1.496153e+11 | CY6: =CP6 + $DV6*$BK6^2 * $CV$2 -> 1.4948894e+11 | CZ6: =CQ6 + $DV6*$BK6*$BL6 * $CV$2 -> 15478048 | DA6: =-CW6 -> -0.74741996 | DB6: =-CZ6 -> -15478048 | DC6: =-CT6 -> -1302331.7 | DD6: =$DV6*BT6 -> -21653047 | DE6: =$DV6*BS6 -> -1.0432254e+09 | DF6: =CR6*BR6 -> 38451556 | DG6: =CS6*BQ6 -> -1.4330099e+08 | DI6: =IF($DI$3=1,-AB6, 0) -> 15.5946 | DJ6: =RADIANS(DI6) -> 0.27217712 | DK6: 1 | DL6: 0 | DM6: =AA6 -> 0 | DN6: 0 | DO6: 0 | DP6: =AL6 -> 3126.5244 | DQ6: =BX6 -> -0.02200188 | DR6: =BY6 -> -0.006288586 | DS6: =0.5*($CU6+$CV6)+0.5*($CU6-$CV6)*COS(2*$DJ6) + $DA6*SIN(2*$DJ6) -> 10160.58 | DT6: =0.5*($CU6+$CV6)-0.5*($CU6-$CV6)*COS(2*$DJ6) - $DA6*SIN(2*$DJ6) -> 10156.473 | DU6: =- 0.5*($CU6-$CV6)*SIN(2*$DJ6) + $DA6*COS(2*$DJ6) -> -2.1169362 | DV6: =AS6*AZ6 -> 4.5425027e+10 | DW6: =$DD6*COS($DJ6) + $DE6*SIN($DJ6) -> -3.0130525e+08 | DX6: =- $DD6*SIN($DJ6) + $DE6*COS($DJ6) -> -9.9900116e+08 | DY6: =0.5*($CX6+$CY6)+0.5*($CX6-$CY6)*COS(2*$DJ6) + $DB6*SIN(2*$DJ6) -> 1.4959816e+11 | DZ6: =0.5*($CX6+$CY6)-0.5*($CX6-$CY6)*COS(2*$DJ6) - $DB6*SIN(2*$DJ6) -> 1.4950609e+11 | EA6: =- 0.5*($CX6-$CY6)*SIN(2*$DJ6) + $DB6*COS(2*$DJ6) -> -45961067 | EB6: =CI6 -> 8.7412032e+10 | EC6: =0.5*($CR6+$CS6)+0.5*($CR6-$CS6)*COS(2*$DJ6) - $DC6*SIN(2*$DJ6) -> 6.7282758e+09 | ED6: =0.5*($CR6+$CS6)-0.5*($CR6-$CS6)*COS(2*$DJ6) + $DC6*SIN(2*$DJ6) -> 6.7374096e+09 | EE6: =0.5*($CR6-$CS6)*SIN(2*$DJ6) + $DC6*COS(2*$DJ6) -> -4287005.4 | EF6: =$DF6*COS($DJ6) + $DG6*SIN($DJ6) -> -1487395.7 | EG6: =- $DF6*SIN($DJ6) + $DG6*COS($DJ6) -> -1.4836268e+08 | EH6: 0 | EJ6: =$DV6*BL6 -> -21653047 | EK6: =$DV6*BK6 -> 1.0432254e+09 | EL6: =CR6*BJ6 -> 38451556 | EM6: =CS6*BI6 -> 1.4330099e+08 | EO6: =0.5*($CU6+$CV6)+0.5*($CU6-$CV6)*COS(2*$DJ6) - $CW6*SIN(2*$DJ6) -> 10160.58 | EP6: =0.5*($CU6+$CV6)-0.5*($CU6-$CV6)*COS(2*$DJ6) + $CW6*SIN(2*$DJ6) -> 10156.473 | EQ6: =0.5*($CU6-$CV6)*SIN(2*$DJ6) + $CW6*COS(2*$DJ6) -> 2.1169362 | ER6: =-EQ6 -> -2.1169362 | ES6: =$EJ6*COS($DJ6) - $EK6*SIN($DJ6) -> -3.0130525e+08 | ET6: =$EJ6*SIN($DJ6) + $EK6*COS($DJ6) -> 9.9900116e+08 | EU6: =-ET6 -> -9.9900116e+08 | EV6: =0.5*($CX6+$CY6)+0.5*($CX6-$CY6)*COS(2*$DJ6) - $CZ6*SIN(2*$DJ6) -> 1.4959816e+11 | EW6: =0.5*($CX6+$CY6)-0.5*($CX6-$CY6)*COS(2*$DJ6) + $CZ6*SIN(2*$DJ6) -> 1.4950609e+11 | EX6: =0.5*($CX6-$CY6)*SIN(2*$DJ6) + $CZ6*COS(2*$DJ6) -> 45961067 | EY6: =-EX6 -> -45961067 | EZ6: =0.5*($CR6+$CS6)+0.5*($CR6-$CS6)*COS(2*$DJ6) + $CT6*SIN(2*$DJ6) -> 6.7282758e+09 | FA6: =0.5*($CR6+$CS6)-0.5*($CR6-$CS6)*COS(2*$DJ6) - $CT6*SIN(2*$DJ6) -> 6.7374096e+09 | FB6: =- 0.5*($CR6-$CS6)*SIN(2*$DJ6) + $CT6*COS(2*$DJ6) -> 4287005.4 | FC6: =-FB6 -> -4287005.4 | FD6: =$EL6*COS($DJ6) - $EM6*SIN($DJ6) -> -1487395.7 | FE6: =$EL6*SIN($DJ6) + $EM6*COS($DJ6) -> 1.4836268e+08 | FF6: =-FE6 -> -1.4836268e+08 | FH6: =$DV6*CC6 -> -3.0130525e+08 | FI6: =$DV6*CB6 -> -9.9900116e+08 | FJ6: =EZ6*CA6 -> -1417675.3 | FK6: =FA6*BZ6 -> -1.4834716e+08 | FM6: =_xlfn.XLOOKUP(FQ6,$DM$6:$DM$200,$DK$6:$DK$200, ,-1) -> 1 | FN6: =FM6+1 -> 2 | FP6: 1 | FQ6: 0 | FR6: =_xlfn.LET( _xlpm.r, $FQ6, _xlpm.rp, _xlfn.XLOOKUP($FM6,$DK$6:$DK$200,$DM$6:$DM$200, , -1), _xlpm.rn, _xlfn.XLOOKUP($FN6,$DK$6:$DK$200,$DM$6:$DM$200, , -1), _xlpm.xp, _xlfn.XLOOKUP($FM6,$DK$6:$DK$200,DN$6:DN$200, , -1), _xlpm.xn, _xlfn.XLOOKUP($FN6,$DK$6:$DK$200,DN$6:DN$200, , -1), (_xlpm.r - _xlpm.rp)/(_xlpm.rn - _xlpm.rp)*(_xlpm.xn - _xlpm.xp) + _xlpm.xp ) -> 0 | FS6: =_xlfn.LET( _xlpm.r, $FQ6, _xlpm.rp, _xlfn.XLOOKUP($FM6,$DK$6:$DK$200,$DM$6:$DM$200, , -1), _xlpm.rn, _xlfn.XLOOKUP($FN6,$DK$6:$DK$200,$DM$6:$DM$200, , -1), _xlpm.xp, _xlfn.XLOOKUP($FM6,$DK$6:$DK$200,DO$6:DO$200, , -1), _xlpm.xn, _xlfn.XLOOKUP($FN6,$DK$6:$DK$200,DO$6:DO$200, , -1), (_xlpm.r - _xlpm.rp)/(_xlpm.rn - _xlpm.rp)*(_xlpm.xn - _xlpm.xp) + _xlpm.xp ) -> 0 | FT6: =_xlfn.LET( _xlpm.r, $FQ6, _xlpm.rp, _xlfn.XLOOKUP($FM6,$DK$6:$DK$200,$DM$6:$DM$200, , -1), _xlpm.rn, _xlfn.XLOOKUP($FN6,$DK$6:$DK$200,$DM$6:$DM$200, , -1), _xlpm.xp, _xlfn.XLOOKUP($FM6,$DK$6:$DK$200,DP$6:DP$200, , -1), _xlpm.xn, _xlfn.XLOOKUP($FN6,$DK$6:$DK$200,DP$6:DP$200, , -1), (_xlpm.r - _xlpm.rp)/(_xlpm.rn - _xlpm.rp)*(_xlpm.xn - _xlpm.xp) + _xlpm.xp ) -> 3126.5244 | FU6: =_xlfn.LET( _xlpm.r, $FQ6, _xlpm.rp, _xlfn.XLOOKUP($FM6,$DK$6:$DK$200,$DM$6:$DM$200, , -1), _xlpm.rn, _xlfn.XLOOKUP($FN6,$DK$6:$DK$200,$DM$6:$DM$200, , -1), _xlpm.xp, _xlfn.XLOOKUP($FM6,$DK$6:$DK$200,DQ$6:DQ$200, , -1), _xlpm.xn, _xlfn.XLOOKUP($FN6,$DK$6:$DK$200,DQ$6:DQ$200, , -1), (_xlpm.r - _xlpm.rp)/(_xlpm.rn - _xlpm.rp)*(_xlpm.xn - _xlpm.xp) + _xlpm.xp ) -> -0.02200188 | FV6: =_xlfn.LET( _xlpm.r, $FQ6, _xlpm.rp, _xlfn.XLOOKUP($FM6,$DK$6:$DK$200,$DM$6:$DM$200, , -1), _xlpm.rn, _xlfn.XLOOKUP($FN6,$DK$6:$DK$200,$DM$6:$DM$200, , -1), _xlpm.xp, _xlfn.XLOOKUP($FM6,$DK$6:$DK$200,DR$6:DR$200, , -1), _xlpm.xn, _xlfn.XLOOKUP($FN6,$DK$6:$DK$200,DR$6:DR$200, , -1), (_xlpm.r - _xlpm.rp)/(_xlpm.rn - _xlpm.rp)*(_xlpm.xn - _xlpm.xp) + _xlpm.xp ) -> -0.006288586 | FW6: =_xlfn.LET( _xlpm.r, $FQ6, _xlpm.rp, _xlfn.XLOOKUP($FM6,$DK$6:$DK$200,$DM$6:$DM$200, , -1), _xlpm.rn, _xlfn.XLOOKUP($FN6,$DK$6:$DK$200,$DM$6:$DM$200, , -1), _xlpm.xp, _xlfn.XLOOKUP($FM6,$DK$6:$DK$200,DS$6:DS$200, , -1), _xlpm.xn, _xlfn.XLOOKUP($FN6,$DK$6:$DK$200,DS$6:DS$200, , -1), (_xlpm.r - _xlpm.rp)/(_xlpm.rn - _xlpm.rp)*(_xlpm.xn - _xlpm.xp) + _xlpm.xp ) -> 10160.58 | FX6: =_xlfn.LET( _xlpm.r, $FQ6, _xlpm.rp, _xlfn.XLOOKUP($FM6,$DK$6:$DK$200,$DM$6:$DM$200, , -1), _xlpm.rn, _xlfn.XLOOKUP($FN6,$DK$6:$DK$200,$DM$6:$DM$200, , -1), _xlpm.xp, _xlfn.XLOOKUP($FM6,$DK$6:$DK$200,DT$6:DT$200, , -1), _xlpm.xn, _xlfn.XLOOKUP($FN6,$DK$6:$DK$200,DT$6:DT$200, , -1), (_xlpm.r - _xlpm.rp)/(_xlpm.rn - _xlpm.rp)*(_xlpm.xn - _xlpm.xp) + _xlpm.xp ) -> 10156.473 | FY6: =_xlfn.LET( _xlpm.r, $FQ6, _xlpm.rp, _xlfn.XLOOKUP($FM6,$DK$6:$DK$200,$DM$6:$DM$200, , -1), _xlpm.rn, _xlfn.XLOOKUP($FN6,$DK$6:$DK$200,$DM$6:$DM$200, , -1), _xlpm.xp, _xlfn.XLOOKUP($FM6,$DK$6:$DK$200,DU$6:DU$200, , -1), _xlpm.xn, _xlfn.XLOOKUP($FN6,$DK$6:$DK$200,DU$6:DU$200, , -1), (_xlpm.r - _xlpm.rp)/(_xlpm.rn - _xlpm.rp)*(_xlpm.xn - _xlpm.xp) + _xlpm.xp ) -> -2.1169362 | ... GH6: =_xlfn.LET( _xlpm.r, $FQ6, _xlpm.rp, _xlfn.XLOOKUP($FM6,$DK$6:$DK$200,$DM$6:$DM$200, , -1), _xlpm.rn, _xlfn.XLOOKUP($FN6,$DK$6:$DK$200,$DM$6:$DM$200, , -1), _xlpm.xp, _xlfn.XLOOKUP($FM6,$DK$6:$DK$200,ED$6:ED$200, , -1), _xlpm.xn, _xlfn.XLOOKUP($FN6,$DK$6:$DK$200,ED$6:ED$200, , -1), (_xlpm.r - _xlpm.rp)/(_xlpm.rn - _xlpm.rp)*(_xlpm.xn - _xlpm.xp) + _xlpm.xp ) -> 6.7374096e+09 | GI6: =_xlfn.LET( _xlpm.r, $FQ6, _xlpm.rp, _xlfn.XLOOKUP($FM6,$DK$6:$DK$200,$DM$6:$DM$200, , -1), _xlpm.rn, _xlfn.XLOOKUP($FN6,$DK$6:$DK$200,$DM$6:$DM$200, , -1), _xlpm.xp, _xlfn.XLOOKUP($FM6,$DK$6:$DK$200,EF$6:EF$200, , -1), _xlpm.xn, _xlfn.XLOOKUP($FN6,$DK$6:$DK$200,EF$6:EF$200, , -1), (_xlpm.r - _xlpm.rp)/(_xlpm.rn - _xlpm.rp)*(_xlpm.xn - _xlpm.xp) + _xlpm.xp ) -> -1487395.7 | GJ6: =_xlfn.LET( _xlpm.r, $FQ6, _xlpm.rp, _xlfn.XLOOKUP($FM6,$DK$6:$DK$200,$DM$6:$DM$200, , -1), _xlpm.rn, _xlfn.XLOOKUP($FN6,$DK$6:$DK$200,$DM$6:$DM$200, , -1), _xlpm.xp, _xlfn.XLOOKUP($FM6,$DK$6:$DK$200,EG$6:EG$200, , -1), _xlpm.xn, _xlfn.XLOOKUP($FN6,$DK$6:$DK$200,EG$6:EG$200, , -1), (_xlpm.r - _xlpm.rp)/(_xlpm.rn - _xlpm.rp)*(_xlpm.xn - _xlpm.xp) + _xlpm.xp ) -> -1.4836268e+08 | GK6: =_xlfn.LET( _xlpm.r, $FQ6, _xlpm.rp, _xlfn.XLOOKUP($FM6,$DK$6:$DK$200,$DM$6:$DM$200, , -1), _xlpm.rn, _xlfn.XLOOKUP($FN6,$DK$6:$DK$200,$DM$6:$DM$200, , -1), _xlpm.xp, _xlfn.XLOOKUP($FM6,$DK$6:$DK$200,EH$6:EH$200, , -1), _xlpm.xn, _xlfn.XLOOKUP($FN6,$DK$6:$DK$200,EH$6:EH$200, , -1), (_xlpm.r - _xlpm.rp)/(_xlpm.rn - _xlpm.rp)*(_xlpm.xn - _xlpm.xp) + _xlpm.xp ) -> 0
