Workbook

Sheet READ_ME
B2: Tabs | C2: Details | D2: Notes | F2: Abbreviations
B3: NASA | C3: Raw data of noFPM structural models of HVAB | D3: SI units convertion | F3: FPM | G3: Fully Populated Matrix
B4: NASA_2_CORAL | C4: Process noFPM data to use as input in CORAL | D4: discussion about axes rotation | F4: 2 | G4: to
B5: beam_frmt | C5: beam.str format | D5: used for "output" | F5: diff | G5: differences
B6: EXI_beam_diff | C6: Comparison of "NASA_2_CORAL_noFPM" & "EXI_beam" models | D6: plots, [%] differences | F6: frmt | G6: format
B7: output | C7: TXT format of beam.str | D7: "beam_frmt" | F7: EXI | G7: existing
B8: EXI_beam | C8: Existing beam.str | D8: Diploma thesis beam.str

Sheet NASA
B1: NASA | V1: NASA | AE1: NASA | AL1: NASA | BE1: initialization | BI1: NASA
B2: File Name: | C2: https://www.aiaa-hpw.org/_files/ugd/0bda64_8380011662e748a2bde4a3ecefe95fd1.pdf | V2: File Name: | W2: https://www.aiaa-hpw.org/_files/ugd/0bda64_8380011662e748a2bde4a3ecefe95fd1.pdf | AL2: File Name: | AM2: https://www.aiaa-hpw.org/_files/ugd/0bda64_8380011662e748a2bde4a3ecefe95fd1.pdf | BE2: R | BF2: 66.5 | BG2: [in] | BI2: File Name:
B3: Details: | C3: RAW | D3: DATA | E3: Structural properties for blade model: standard Timoshenko beam | V3: Details: | W3: RAW | X3: DATA | Y3: Geometric properties of blade | AE3: Details: | AF3: PROCESS | AL3: Details: | AM3: COPY | AN3: DATA | AO3: Structural properties for blade model: standard Timoshenko beam | BE3: h_hinge | BF3: 3.5 | BG3: [in] | BI3: Details: | BJ3: PROCESS | BL3: DATA | BM3: Structural properties in SI untis
AM4: PROCESS | BE4: h_link | BF4: 5.8 | BG4: [in] | BI4: Notes: | BJ4: NASA | BK4: units | BL4: in | BM4: lbf*s^2 / in^2 | BN4: lbf | BO4: lbf*in^2 | BP4: in | BQ4: in | BR4: in | BS4: in | BT4: in | BU4: in | BV4: lbf*in^2 | BW4: lbf*in^2 | BX4: lbf*in^2 | BY4: lbf*s^2 | BZ4: lbf*s^2 | CA4: lbf*s^2
B5: r/R | C5: R | D5: rA | E5: EA | F5: GJ@SC | G5: SCη | H5: SCζ | I5: CGη | J5: CGζ | K5: η | L5: ζ | M5: EI_f | N5: EI_c | O5: EI_fc | P5: I_f | Q5: I_c | R5: I_fc | U5: R | W5: r/R | X5: Twist | Y5: c | Z5: Sweep | AA5: DX | AB5: DY | AC5: DZ | AE5: LOOKUP | AG5: Twist | AH5: c | AI5: Sweep | AL5: r/R | AM5: R | AN5: rA | AO5: EA | AP5: GJ@SC | AQ5: SCη | AR5: SCζ | AS5: CGη | AT5: CGζ | AU5: η | AV5: ζ | AW5: EI_f | AX5: EI_c | AY5: EI_fc | AZ5: I_f | BA5: I_c | BB5: I_fc | BI5: Twist | BJ5: c | BK5: sweep | BL5: R | BM5: rA | BN5: EA | BO5: GJ@SC | BP5: SCη | BQ5: SCζ | BR5: CGη | BS5: CGζ | BT5: η | BU5: ζ | BV5: EI_f | BW5: EI_c | BX5: EI_fc | BY5: I_f | BZ5: I_c | CA5: I_fc | CB5: $ 24
B6: [-] | C6: in | D6: lbf*s^2 / in^2 | E6: lbf | F6: lbf*in^2 | G6: in | H6: in | I6: in | J6: in | K6: in | L6: in | M6: lbf*in^2 | N6: lbf*in^2 | O6: lbf*in^2 | P6: lbf*s^2 | Q6: lbf*s^2 | R6: lbf*s^2 | S6: $ 29 | U6: m | V6: $ 9 | W6: [-] | X6: (deg) | Y6: (in) | Z6: (deg) | AA6: (in) | AB6: (in) | AC6: (in) | AE6: pre | AF6: next | AG6: (deg) | AH6: (in) | AI6: (in) | AJ6: check | AL6: [-] | AM6: in | AN6: lbf*s^2 / in^2 | AO6: lbf | AP6: lbf*in^2 | AQ6: in | AR6: in | AS6: in | AT6: in | AU6: in | AV6: in | AW6: lbf*in^2 | AX6: lbf*in^2 | AY6: lbf*in^2 | AZ6: lbf*s^2 | BA6: lbf*s^2 | BB6: lbf*s^2 | BC6: $ 24 | BE6: conversion units | BI6: deg | BJ6: m | BK6: m | BL6: m | BM6: N*s^2/m^2 | BN6: N | BO6: N*m^2 | BP6: m | BQ6: m | BR6: m | BS6: m | BT6: m | BU6: m | BV6: N*m^2 | BW6: N*m^2 | BX6: N*m^2 | BY6: N*s^2 | BZ6: N*s^2 | CA6: N*s^2
A7: check | B7: =($BF$3+$BF$4)/$BF$2 -> 0.13984962 | C7: =B7* $BF$2 -> 9.3 | D7: =D8 -> 0.000298 | E7: =E8 -> 13000000 | F7: =F8 -> 274000 | G7: =G8 -> 0.127 | H7: =H8 -> 0.012 | I7: =I8 -> 1.279 | J7: =J8 -> -0.027 | K7: =K8 -> -0.001 | ... R7: =R8 -> 1.62e-05 | S7: 1 | U7: =W7* $BF$2 *$BG$8 - $BF$3 *$BG$8 -> 0.14732063 | V7: 1 | W7: 0.13985 | X7: 8.2 | Y7: 5.45 | Z7: 0 | AA7: 9.3 | AB7: 0 | AC7: 0 | AE7: =_xlfn.XLOOKUP(AL7, $W$7:$W$200, $V$7:$V$200, , 1) -> 1 | AF7: =AE7+1 -> 2 | AG7: =_xlfn.LET( _xlpm.r, $AL7, _xlpm.rp, _xlfn.XLOOKUP($AE7, $V$7:$V$202, $W$7:$W$202, , -1), _xlpm.rn, _xlfn.XLOOKUP($AF7, $V$7:$V$202, $W$7:$W$202, , -1), _xlpm.xp, _xlfn.XLOOKUP($AE7, $V$7:$V$202, X$7:X$202, , -1), _xlpm.xn, _xlfn.XLOOKUP($AF7, $V$7:$V$202, X$7:X$202, , -1), (_xlpm.r - _xlpm.rp)/(_xlpm.rn - _xlpm.rp)*(_xlpm.xn - _xlpm.xp) + _xlpm.xp ) -> 8.2 | AH7: =_xlfn.LET( _xlpm.r, $AL7, _xlpm.rp, _xlfn.XLOOKUP($AE7, $V$7:$V$202, $W$7:$W$202, , -1), _xlpm.rn, _xlfn.XLOOKUP($AF7, $V$7:$V$202, $W$7:$W$202, , -1), _xlpm.xp, _xlfn.XLOOKUP($AE7, $V$7:$V$202, Y$7:Y$202, , -1), _xlpm.xn, _xlfn.XLOOKUP($AF7, $V$7:$V$202, Y$7:Y$202, , -1), (_xlpm.r - _xlpm.rp)/(_xlpm.rn - _xlpm.rp)*(_xlpm.xn - _xlpm.xp) + _xlpm.xp ) -> 5.45 | AI7: =- _xlfn.LET( _xlpm.r, $AL7, _xlpm.rp, _xlfn.XLOOKUP($AE7, $V$7:$V$202, $W$7:$W$202, , -1), _xlpm.rn, _xlfn.XLOOKUP($AF7, $V$7:$V$202, $W$7:$W$202, , -1), _xlpm.xp, _xlfn.XLOOKUP($AE7, $V$7:$V$202, AB$7:AB$202, , -1), _xlpm.xn, _xlfn.XLOOKUP($AF7, $V$7:$V$202, AB$7:AB$202, , -1), (_xlpm.r - _xlpm.rp)/(_xlpm.rn - _xlpm.rp)*(_xlpm.xn - _xlpm.xp) + _xlpm.xp ) -> 0 | AJ7: =_xlfn.LET( _xlpm.r, $AL7, _xlpm.rp, _xlfn.XLOOKUP($AE7, $V$7:$V$202, $W$7:$W$202, , -1), _xlpm.rn, _xlfn.XLOOKUP($AF7, $V$7:$V$202, $W$7:$W$202, , -1), _xlpm.xp, _xlfn.XLOOKUP($AE7, $V$7:$V$202, Z$7:Z$202, , -1), _xlpm.xn, _xlfn.XLOOKUP($AF7, $V$7:$V$202, Z$7:Z$202, , -1), (_xlpm.r - _xlpm.rp)/(_xlpm.rn - _xlpm.rp)*(_xlpm.xn - _xlpm.xp) + _xlpm.xp ) -> 0 | AL7: =B7 -> 0.13984962 | AM7: =C7 -> 9.3 | AN7: =AN8 -> 0.000298 | AO7: =AO8 -> 13000000 | AP7: =AP8 -> 274000 | AQ7: =AQ8 -> 0.127 | AR7: =AR8 -> 0.012 | AS7: =AS8 -> 1.279 | AT7: =AT8 -> -0.027 | AU7: =AU8 -> -0.001 | ... BB7: =BB8 -> 1.62e-05 | BC7: 1 | BI7: =AG7 -> 8.2 | BJ7: =AH7 *$BG$8 -> 0.13843 | BK7: =AI7 *$BG$8 -> 0 | BL7: =AM7 * $BG$8 - $BF$3*$BG$8 -> 0.14732 | BM7: =AN7 * $BG$9/ ($BG$8^2) -> 2.0546377 | BN7: =AO7 * $BG$9 -> 57826881 | BO7: =AP7 * $BG$9*$BG$8^2 -> 786.32922 | BP7: =AQ7 * $BG$8 -> 0.0032258 | BQ7: =AR7 * $BG$8 -> 0.0003048 | BR7: =AS7 * $BG$8 -> 0.0324866 | BS7: =AT7 * $BG$8 -> -0.0006858 | BT7: =AU7 * $BG$8 -> -2.54e-05 | BU7: =AV7 * $BG$8 -> -5.08e-05 | BV7: =AW7 * $BG$9*$BG$8^2 -> 828.97179 | BW7: =AX7 * $BG$9*$BG$8^2 -> 20289.59 | BX7: =AY7 * $BG$9*$BG$8^2 -> 94.703884 | BY7: =AZ7 * $BG$9 -> 3.2027196e-05 | BZ7: =BA7 * $BG$9 -> 0.0040300888 | CA7: =BB7 * $BG$9 -> 7.206119e-05 | CB7: 1
A8: =IF(B8=B7, "same", "") | B8: 0.178 | C8: =B8* $BF$2 -> 11.837 | D8: 0.000298 | E8: 13000000 | F8: 274000 | G8: 0.127 | H8: 0.012 | I8: 1.279 | J8: -0.027 | K8: -0.001 | L8: -0.002 | M8: 288859 | N8: 7070000 | O8: 33000 | P8: 7.2e-06 | Q8: 0.000906 | R8: 1.62e-05 | S8: 2 | U8: =W8* $BF$2 *$BG$8 - $BF$3 *$BG$8 -> 0.1935513 | V8: 2 | W8: 0.16722 | X8: 8.2 | Y8: 5.45 | Z8: 0 | AA8: 11.12 | AB8: 0 | AC8: 0 | AE8: =_xlfn.XLOOKUP(AL8, $W$7:$W$200, $V$7:$V$200, , -1) -> 2 | AF8: =AE8+1 -> 3 | AG8: =_xlfn.LET( _xlpm.r, $AL8, _xlpm.rp, _xlfn.XLOOKUP($AE8, $V$7:$V$202, $W$7:$W$202, , -1), _xlpm.rn, _xlfn.XLOOKUP($AF8, $V$7:$V$202, $W$7:$W$202, , -1), _xlpm.xp, _xlfn.XLOOKUP($AE8, $V$7:$V$202, X$7:X$202, , -1), _xlpm.xn, _xlfn.XLOOKUP($AF8, $V$7:$V$202, X$7:X$202, , -1), (_xlpm.r - _xlpm.rp)/(_xlpm.rn - _xlpm.rp)*(_xlpm.xn - _xlpm.xp) + _xlpm.xp ) -> 8.0484739 | AH8: =_xlfn.LET( _xlpm.r, $AL8, _xlpm.rp, _xlfn.XLOOKUP($AE8, $V$7:$V$202, $W$7:$W$202, , -1), _xlpm.rn, _xlfn.XLOOKUP($AF8, $V$7:$V$202, $W$7:$W$202, , -1), _xlpm.xp, _xlfn.XLOOKUP($AE8, $V$7:$V$202, Y$7:Y$202, , -1), _xlpm.xn, _xlfn.XLOOKUP($AF8, $V$7:$V$202, Y$7:Y$202, , -1), (_xlpm.r - _xlpm.rp)/(_xlpm.rn - _xlpm.rp)*(_xlpm.xn - _xlpm.xp) + _xlpm.xp ) -> 5.45 | AI8: =- _xlfn.LET( _xlpm.r, $AL8, _xlpm.rp, _xlfn.XLOOKUP($AE8, $V$7:$V$202, $W$7:$W$202, , -1), _xlpm.rn, _xlfn.XLOOKUP($AF8, $V$7:$V$202, $W$7:$W$202, , -1), _xlpm.xp, _xlfn.XLOOKUP($AE8, $V$7:$V$202, AB$7:AB$202, , -1), _xlpm.xn, _xlfn.XLOOKUP($AF8, $V$7:$V$202, AB$7:AB$202, , -1), (_xlpm.r - _xlpm.rp)/(_xlpm.rn - _xlpm.rp)*(_xlpm.xn - _xlpm.xp) + _xlpm.xp ) -> 0 | AJ8: =_xlfn.LET( _xlpm.r, $AL8, _xlpm.rp, _xlfn.XLOOKUP($AE8, $V$7:$V$202, $W$7:$W$202, , -1), _xlpm.rn, _xlfn.XLOOKUP($AF8, $V$7:$V$202, $W$7:$W$202, , -1), _xlpm.xp, _xlfn.XLOOKUP($AE8, $V$7:$V$202, Z$7:Z$202, , -1), _xlpm.xn, _xlfn.XLOOKUP($AF8, $V$7:$V$202, Z$7:Z$202, , -1), (_xlpm.r - _xlpm.rp)/(_xlpm.rn - _xlpm.rp)*(_xlpm.xn - _xlpm.xp) + _xlpm.xp ) -> 0 | AL8: =B8 -> 0.178 | AM8: =C8 -> 11.837 | AN8: 0.000298 | AO8: 13000000 | AP8: 274000 | AQ8: 0.127 | AR8: 0.012 | AS8: 1.279 | AT8: -0.027 | AU8: -0.001 | AV8: -0.002 | AW8: 288859 | AX8: 7070000 | AY8: 33000 | AZ8: 7.2e-06 | BA8: 0.000906 | BB8: 1.62e-05 | BC8: 2 | BE8: in2m | BF8: [in] to [m] | BG8: 0.0254 | BI8: =AG8 -> 8.0484739 | BJ8: =AH8 *$BG$8 -> 0.13843 | BK8: =AI8 *$BG$8 -> 0 | BL8: =AM8 * $BG$8 - $BF$3*$BG$8 -> 0.2117598 | BM8: =AN8 * $BG$9/ ($BG$8^2) -> 2.0546377 | BN8: =AO8 * $BG$9 -> 57826881 | BO8: =AP8 * $BG$9*$BG$8^2 -> 786.32922 | BP8: =AQ8 * $BG$8 -> 0.0032258 | BQ8: =AR8 * $BG$8 -> 0.0003048 | BR8: =AS8 * $BG$8 -> 0.0324866 | BS8: =AT8 * $BG$8 -> -0.0006858 | BT8: =AU8 * $BG$8 -> -2.54e-05 | BU8: =AV8 * $BG$8 -> -5.08e-05 | BV8: =AW8 * $BG$9*$BG$8^2 -> 828.97179 | BW8: =AX8 * $BG$9*$BG$8^2 -> 20289.59 | BX8: =AY8 * $BG$9*$BG$8^2 -> 94.703884 | BY8: =AZ8 * $BG$9 -> 3.2027196e-05 | BZ8: =BA8 * $BG$9 -> 0.0040300888 | CA8: =BB8 * $BG$9 -> 7.206119e-05 | CB8: 2
A9: =IF(B9=B8, "same", "") | B9: 0.215 | C9: =B9* $BF$2 -> 14.2975 | D9: 0.000219 | E9: 7380000 | F9: 236000 | G9: -0.002 | H9: 0.054 | I9: -0.017 | J9: 0.031 | K9: -0.052 | L9: 0.04 | M9: 308234 | N9: 4540000 | O9: -19900 | P9: 6.16e-06 | Q9: 0.000363 | R9: -1.88e-06 | S9: 3 | U9: =W9* $BF$2 *$BG$8 - $BF$3 *$BG$8 -> 0.33655051 | V9: 3 | W9: 0.25188 | X9: 7.01 | Y9: 5.45 | Z9: 0 | AA9: 16.75 | AB9: 0 | AC9: 0 | AE9: =_xlfn.XLOOKUP(AL9, $W$7:$W$200, $V$7:$V$200, , -1) -> 2 | AF9: =AE9+1 -> 3 | AG9: =_xlfn.LET( _xlpm.r, $AL9, _xlpm.rp, _xlfn.XLOOKUP($AE9, $V$7:$V$202, $W$7:$W$202, , -1), _xlpm.rn, _xlfn.XLOOKUP($AF9, $V$7:$V$202, $W$7:$W$202, , -1), _xlpm.xp, _xlfn.XLOOKUP($AE9, $V$7:$V$202, X$7:X$202, , -1), _xlpm.xn, _xlfn.XLOOKUP($AF9, $V$7:$V$202, X$7:X$202, , -1), (_xlpm.r - _xlpm.rp)/(_xlpm.rn - _xlpm.rp)*(_xlpm.xn - _xlpm.xp) + _xlpm.xp ) -> 7.5283936 | AH9: =_xlfn.LET( _xlpm.r, $AL9, _xlpm.rp, _xlfn.XLOOKUP($AE9, $V$7:$V$202, $W$7:$W$202, , -1), _xlpm.rn, _xlfn.XLOOKUP($AF9, $V$7:$V$202, $W$7:$W$202, , -1), _xlpm.xp, _xlfn.XLOOKUP($AE9, $V$7:$V$202, Y$7:Y$202, , -1), _xlpm.xn, _xlfn.XLOOKUP($AF9, $V$7:$V$202, Y$7:Y$202, , -1), (_xlpm.r - _xlpm.rp)/(_xlpm.rn - _xlpm.rp)*(_xlpm.xn - _xlpm.xp) + _xlpm.xp ) -> 5.45 | AI9: =- _xlfn.LET( _xlpm.r, $AL9, _xlpm.rp, _xlfn.XLOOKUP($AE9, $V$7:$V$202, $W$7:$W$202, , -1), _xlpm.rn, _xlfn.XLOOKUP($AF9, $V$7:$V$202, $W$7:$W$202, , -1), _xlpm.xp, _xlfn.XLOOKUP($AE9, $V$7:$V$202, AB$7:AB$202, , -1), _xlpm.xn, _xlfn.XLOOKUP($AF9, $V$7:$V$202, AB$7:AB$202, , -1), (_xlpm.r - _xlpm.rp)/(_xlpm.rn - _xlpm.rp)*(_xlpm.xn - _xlpm.xp) + _xlpm.xp ) -> 0 | AJ9: =_xlfn.LET( _xlpm.r, $AL9, _xlpm.rp, _xlfn.XLOOKUP($AE9, $V$7:$V$202, $W$7:$W$202, , -1), _xlpm.rn, _xlfn.XLOOKUP($AF9, $V$7:$V$202, $W$7:$W$202, , -1), _xlpm.xp, _xlfn.XLOOKUP($AE9, $V$7:$V$202, Z$7:Z$202, , -1), _xlpm.xn, _xlfn.XLOOKUP($AF9, $V$7:$V$202, Z$7:Z$202, , -1), (_xlpm.r - _xlpm.rp)/(_xlpm.rn - _xlpm.rp)*(_xlpm.xn - _xlpm.xp) + _xlpm.xp ) -> 0 | AL9: =B9 -> 0.215 | AM9: =C9 -> 14.2975 | AN9: 0.000219 | AO9: 7380000 | AP9: 236000 | AQ9: -0.002 | AR9: 0.054 | AS9: -0.017 | AT9: 0.031 | AU9: -0.052 | AV9: 0.04 | AW9: 308234 | AX9: 4540000 | AY9: -19900 | AZ9: 6.16e-06 | BA9: 0.000363 | BB9: -1.88e-06 | BC9: 3 | BE9: lbf2N | BF9: [lbf] to [N] | BG9: 4.4482216 | BI9: =AG9 -> 7.5283936 | BJ9: =AH9 *$BG$8 -> 0.13843 | BK9: =AI9 *$BG$8 -> 0 | BL9: =AM9 * $BG$8 - $BF$3*$BG$8 -> 0.2742565 | BM9: =AN9 * $BG$9/ ($BG$8^2) -> 1.5099518 | BN9: =AO9 * $BG$9 -> 32827876 | BO9: =AP9 * $BG$9*$BG$8^2 -> 677.27626 | BP9: =AQ9 * $BG$8 -> -5.08e-05 | BQ9: =AR9 * $BG$8 -> 0.0013716 | BR9: =AS9 * $BG$8 -> -0.0004318 | BS9: =AT9 * $BG$8 -> 0.0007874 | BT9: =AU9 * $BG$8 -> -0.0013208 | BU9: =AV9 * $BG$8 -> 0.001016 | BV9: =AW9 * $BG$9*$BG$8^2 -> 884.57445 | BW9: =AX9 * $BG$9*$BG$8^2 -> 13028.959 | BX9: =AY9 * $BG$9*$BG$8^2 -> -57.109312 | BY9: =AZ9 * $BG$9 -> 2.7401045e-05 | BZ9: =BA9 * $BG$9 -> 0.0016147044 | CA9: =BB9 * $BG$9 -> -8.3626566e-06 | CB9: 3
A10: =IF(B10=B9, "same", "") | B10: 0.252 | C10: =B10* $BF$2 -> 16.758 | D10: 0.000206 | E10: 6280000 | F10: 214000 | G10: 0.031 | H10: 0.112 | I10: -0.05 | J10: 0.056 | K10: -0.051 | L10: 0.078 | M10: 345802 | N10: 4030000 | O10: -55600 | P10: 6.75e-06 | Q10: 0.000336 | R10: -5.93e-06 | S10: 4 | U10: =W10* $BF$2 *$BG$8 - $BF$3 *$BG$8 -> 1.011177 | V10: 4 | W10: 0.65128 | X10: 1.4 | Y10: 5.45 | Z10: 0 | AA10: 43.31 | AB10: 0 | AC10: 0 | AE10: =_xlfn.XLOOKUP(AL10, $W$7:$W$200, $V$7:$V$200, , -1) -> 3 | AF10: =AE10+1 -> 4 | AG10: =_xlfn.LET( _xlpm.r, $AL10, _xlpm.rp, _xlfn.XLOOKUP($AE10, $V$7:$V$202, $W$7:$W$202, , -1), _xlpm.rn, _xlfn.XLOOKUP($AF10, $V$7:$V$202, $W$7:$W$202, , -1), _xlpm.xp, _xlfn.XLOOKUP($AE10, $V$7:$V$202, X$7:X$202, , -1), _xlpm.xn, _xlfn.XLOOKUP($AF10, $V$7:$V$202, X$7:X$202, , -1), (_xlpm.r - _xlpm.rp)/(_xlpm.rn - _xlpm.rp)*(_xlpm.xn - _xlpm.xp) + _xlpm.xp ) -> 7.0083145 | AH10: =_xlfn.LET( _xlpm.r, $AL10, _xlpm.rp, _xlfn.XLOOKUP($AE10, $V$7:$V$202, $W$7:$W$202, , -1), _xlpm.rn, _xlfn.XLOOKUP($AF10, $V$7:$V$202, $W$7:$W$202, , -1), _xlpm.xp, _xlfn.XLOOKUP($AE10, $V$7:$V$202, Y$7:Y$202, , -1), _xlpm.xn, _xlfn.XLOOKUP($AF10, $V$7:$V$202, Y$7:Y$202, , -1), (_xlpm.r - _xlpm.rp)/(_xlpm.rn - _xlpm.rp)*(_xlpm.xn - _xlpm.xp) + _xlpm.xp ) -> 5.45 | AI10: =- _xlfn.LET( _xlpm.r, $AL10, _xlpm.rp, _xlfn.XLOOKUP($AE10, $V$7:$V$202, $W$7:$W$202, , -1), _xlpm.rn, _xlfn.XLOOKUP($AF10, $V$7:$V$202, $W$7:$W$202, , -1), _xlpm.xp, _xlfn.XLOOKUP($AE10, $V$7:$V$202, AB$7:AB$202, , -1), _xlpm.xn, _xlfn.XLOOKUP($AF10, $V$7:$V$202, AB$7:AB$202, , -1), (_xlpm.r - _xlpm.rp)/(_xlpm.rn - _xlpm.rp)*(_xlpm.xn - _xlpm.xp) + _xlpm.xp ) -> 0 | AJ10: =_xlfn.LET( _xlpm.r, $AL10, _xlpm.rp, _xlfn.XLOOKUP($AE10, $V$7:$V$202, $W$7:$W$202, , -1), _xlpm.rn, _xlfn.XLOOKUP($AF10, $V$7:$V$202, $W$7:$W$202, , -1), _xlpm.xp, _xlfn.XLOOKUP($AE10, $V$7:$V$202, Z$7:Z$202, , -1), _xlpm.xn, _xlfn.XLOOKUP($AF10, $V$7:$V$202, Z$7:Z$202, , -1), (_xlpm.r - _xlpm.rp)/(_xlpm.rn - _xlpm.rp)*(_xlpm.xn - _xlpm.xp) + _xlpm.xp ) -> 0 | AL10: =B10 -> 0.252 | AM10: =C10 -> 16.758 | AN10: 0.000206 | AO10: 6280000 | AP10: 214000 | AQ10: 0.031 | AR10: 0.112 | AS10: -0.05 | AT10: 0.056 | AU10: -0.051 | AV10: 0.078 | AW10: 345802 | AX10: 4030000 | AY10: -55600 | AZ10: 6.75e-06 | BA10: 0.000336 | BB10: -5.93e-06 | BC10: 4 | BI10: =AG10 -> 7.0083145 | BJ10: =AH10 *$BG$8 -> 0.13843 | BK10: =AI10 *$BG$8 -> 0 | BL10: =AM10 * $BG$8 - $BF$3*$BG$8 -> 0.3367532 | BM10: =AN10 * $BG$9/ ($BG$8^2) -> 1.42032 | BN10: =AO10 * $BG$9 -> 27934832 | BO10: =AP10 * $BG$9*$BG$8^2 -> 614.14034 | BP10: =AQ10 * $BG$8 -> 0.0007874 | BQ10: =AR10 * $BG$8 -> 0.0028448 | BR10: =AS10 * $BG$8 -> -0.00127 | BS10: =AT10 * $BG$8 -> 0.0014224 | BT10: =AU10 * $BG$8 -> -0.0012954 | BU10: =AV10 * $BG$8 -> 0.0019812 | BV10: =AW10 * $BG$9*$BG$8^2 -> 992.38765 | BW10: =AX10 * $BG$9*$BG$8^2 -> 11565.353 | BX10: =AY10 * $BG$9*$BG$8^2 -> -159.56169 | BY10: =AZ10 * $BG$9 -> 3.0025496e-05 | BZ10: =BA10 * $BG$9 -> 0.0014946025 | CA10: =BB10 * $BG$9 -> -2.6377954e-05 | CB10: 4
A11: =IF(B11=B10, "same", "") | B11: 0.389 | C11: =B11* $BF$2 -> 25.8685 | D11: 0.000158 | E11: 6190000 | F11: 169000 | G11: 0.081 | H11: 0.134 | I11: 0.665 | J11: 0.056 | K11: -0.026 | L11: 0.112 | M11: 259208 | N11: 3930000 | O11: -19500 | P11: 6.54e-06 | Q11: 0.000262 | R11: 2.82e-06 | S11: 5 | U11: =W11* $BF$2 *$BG$8 - $BF$3 *$BG$8 -> 1.0954969 | V11: 5 | W11: 0.7012 | X11: 0.7 | Y11: 5.45 | Z11: 0 | AA11: 46.63 | AB11: 0 | AC11: 0 | AE11: =_xlfn.XLOOKUP(AL11, $W$7:$W$200, $V$7:$V$200, , -1) -> 3 | AF11: =AE11+1 -> 4 | AG11: =_xlfn.LET( _xlpm.r, $AL11, _xlpm.rp, _xlfn.XLOOKUP($AE11, $V$7:$V$202, $W$7:$W$202, , -1), _xlpm.rn, _xlfn.XLOOKUP($AF11, $V$7:$V$202, $W$7:$W$202, , -1), _xlpm.xp, _xlfn.XLOOKUP($AE11, $V$7:$V$202, X$7:X$202, , -1), _xlpm.xn, _xlfn.XLOOKUP($AF11, $V$7:$V$202, X$7:X$202, , -1), (_xlpm.r - _xlpm.rp)/(_xlpm.rn - _xlpm.rp)*(_xlpm.xn - _xlpm.xp) + _xlpm.xp ) -> 5.084003 | AH11: =_xlfn.LET( _xlpm.r, $AL11, _xlpm.rp, _xlfn.XLOOKUP($AE11, $V$7:$V$202, $W$7:$W$202, , -1), _xlpm.rn, _xlfn.XLOOKUP($AF11, $V$7:$V$202, $W$7:$W$202, , -1), _xlpm.xp, _xlfn.XLOOKUP($AE11, $V$7:$V$202, Y$7:Y$202, , -1), _xlpm.xn, _xlfn.XLOOKUP($AF11, $V$7:$V$202, Y$7:Y$202, , -1), (_xlpm.r - _xlpm.rp)/(_xlpm.rn - _xlpm.rp)*(_xlpm.xn - _xlpm.xp) + _xlpm.xp ) -> 5.45 | AI11: =- _xlfn.LET( _xlpm.r, $AL11, _xlpm.rp, _xlfn.XLOOKUP($AE11, $V$7:$V$202, $W$7:$W$202, , -1), _xlpm.rn, _xlfn.XLOOKUP($AF11, $V$7:$V$202, $W$7:$W$202, , -1), _xlpm.xp, _xlfn.XLOOKUP($AE11, $V$7:$V$202, AB$7:AB$202, , -1), _xlpm.xn, _xlfn.XLOOKUP($AF11, $V$7:$V$202, AB$7:AB$202, , -1), (_xlpm.r - _xlpm.rp)/(_xlpm.rn - _xlpm.rp)*(_xlpm.xn - _xlpm.xp) + _xlpm.xp ) -> 0 | AJ11: =_xlfn.LET( _xlpm.r, $AL11, _xlpm.rp, _xlfn.XLOOKUP($AE11, $V$7:$V$202, $W$7:$W$202, , -1), _xlpm.rn, _xlfn.XLOOKUP($AF11, $V$7:$V$202, $W$7:$W$202, , -1), _xlpm.xp, _xlfn.XLOOKUP($AE11, $V$7:$V$202, Z$7:Z$202, , -1), _xlpm.xn, _xlfn.XLOOKUP($AF11, $V$7:$V$202, Z$7:Z$202, , -1), (_xlpm.r - _xlpm.rp)/(_xlpm.rn - _xlpm.rp)*(_xlpm.xn - _xlpm.xp) + _xlpm.xp ) -> 0 | AL11: =B11 -> 0.389 | AM11: =C11 -> 25.8685 | AN11: 0.000158 | AO11: 6190000 | AP11: 169000 | AQ11: 0.081 | AR11: 0.134 | AS11: 0.665 | AT11: 0.056 | AU11: -0.026 | AV11: 0.112 | AW11: 259208 | AX11: 3930000 | AY11: -19500 | AZ11: 6.54e-06 | BA11: 0.000262 | BB11: 2.82e-06 | BC11: 5 | BI11: =AG11 -> 5.084003 | BJ11: =AH11 *$BG$8 -> 0.13843 | BK11: =AI11 *$BG$8 -> 0 | BL11: =AM11 * $BG$8 - $BF$3*$BG$8 -> 0.5681599 | BM11: =AN11 * $BG$9/ ($BG$8^2) -> 1.0893717 | BN11: =AO11 * $BG$9 -> 27534492 | BO11: =AP11 * $BG$9*$BG$8^2 -> 484.99868 | BP11: =AQ11 * $BG$8 -> 0.0020574 | BQ11: =AR11 * $BG$8 -> 0.0034036 | BR11: =AS11 * $BG$8 -> 0.016891 | BS11: =AT11 * $BG$8 -> 0.0014224 | BT11: =AU11 * $BG$8 -> -0.0006604 | BU11: =AV11 * $BG$8 -> 0.0028448 | BV11: =AW11 * $BG$9*$BG$8^2 -> 743.87892 | BW11: =AX11 * $BG$9*$BG$8^2 -> 11278.372 | BX11: =AY11 * $BG$9*$BG$8^2 -> -55.961386 | BY11: =AZ11 * $BG$9 -> 2.9091369e-05 | BZ11: =BA11 * $BG$9 -> 0.0011654341 | CA11: =BB11 * $BG$9 -> 1.2543985e-05 | CB11: 5
A12: =IF(B12=B11, "same", "") | B12: 0.405 | C12: =B12* $BF$2 -> 26.9325 | D12: 0.000157 | E12: 6190000 | F12: 168000 | G12: 0.089 | H12: 0.091 | I12: 0.66 | J12: 0.097 | K12: -0.025 | L12: 0.047 | M12: 258124 | N12: 3920000 | O12: -69700 | P12: 6.43e-06 | Q12: 0.000263 | R12: -1.15e-06 | S12: 6 | U12: =W12* $BF$2 *$BG$8 - $BF$3 *$BG$8 -> 1.2636468 | V12: 6 | W12: 0.80075 | X12: -0.7 | Y12: 5.45 | Z12: 0 | AA12: 53.25 | AB12: 0 | AC12: 0 | AE12: =_xlfn.XLOOKUP(AL12, $W$7:$W$200, $V$7:$V$200, , -1) -> 3 | AF12: =AE12+1 -> 4 | AG12: =_xlfn.LET( _xlpm.r, $AL12, _xlpm.rp, _xlfn.XLOOKUP($AE12, $V$7:$V$202, $W$7:$W$202, , -1), _xlpm.rn, _xlfn.XLOOKUP($AF12, $V$7:$V$202, $W$7:$W$202, , -1), _xlpm.xp, _xlfn.XLOOKUP($AE12, $V$7:$V$202, X$7:X$202, , -1), _xlpm.xn, _xlfn.XLOOKUP($AF12, $V$7:$V$202, X$7:X$202, , -1), (_xlpm.r - _xlpm.rp)/(_xlpm.rn - _xlpm.rp)*(_xlpm.xn - _xlpm.xp) + _xlpm.xp ) -> 4.8592659 | AH12: =_xlfn.LET( _xlpm.r, $AL12, _xlpm.rp, _xlfn.XLOOKUP($AE12, $V$7:$V$202, $W$7:$W$202, , -1), _xlpm.rn, _xlfn.XLOOKUP($AF12, $V$7:$V$202, $W$7:$W$202, , -1), _xlpm.xp, _xlfn.XLOOKUP($AE12, $V$7:$V$202, Y$7:Y$202, , -1), _xlpm.xn, _xlfn.XLOOKUP($AF12, $V$7:$V$202, Y$7:Y$202, , -1), (_xlpm.r - _xlpm.rp)/(_xlpm.rn - _xlpm.rp)*(_xlpm.xn - _xlpm.xp) + _xlpm.xp ) -> 5.45 | AI12: =- _xlfn.LET( _xlpm.r, $AL12, _xlpm.rp, _xlfn.XLOOKUP($AE12, $V$7:$V$202, $W$7:$W$202, , -1), _xlpm.rn, _xlfn.XLOOKUP($AF12, $V$7:$V$202, $W$7:$W$202, , -1), _xlpm.xp, _xlfn.XLOOKUP($AE12, $V$7:$V$202, AB$7:AB$202, , -1), _xlpm.xn, _xlfn.XLOOKUP($AF12, $V$7:$V$202, AB$7:AB$202, , -1), (_xlpm.r - _xlpm.rp)/(_xlpm.rn - _xlpm.rp)*(_xlpm.xn - _xlpm.xp) + _xlpm.xp ) -> 0 | AJ12: =_xlfn.LET( _xlpm.r, $AL12, _xlpm.rp, _xlfn.XLOOKUP($AE12, $V$7:$V$202, $W$7:$W$202, , -1), _xlpm.rn, _xlfn.XLOOKUP($AF12, $V$7:$V$202, $W$7:$W$202, , -1), _xlpm.xp, _xlfn.XLOOKUP($AE12, $V$7:$V$202, Z$7:Z$202, , -1), _xlpm.xn, _xlfn.XLOOKUP($AF12, $V$7:$V$202, Z$7:Z$202, , -1), (_xlpm.r - _xlpm.rp)/(_xlpm.rn - _xlpm.rp)*(_xlpm.xn - _xlpm.xp) + _xlpm.xp ) -> 0 | AL12: =B12 -> 0.405 | AM12: =C12 -> 26.9325 | AN12: 0.000157 | AO12: 6190000 | AP12: 168000 | AQ12: 0.089 | AR12: 0.091 | AS12: 0.66 | AT12: 0.097 | AU12: -0.025 | AV12: 0.047 | AW12: 258124 | AX12: 3920000 | AY12: -69700 | AZ12: 6.43e-06 | BA12: 0.000263 | BB12: -1.15e-06 | BC12: 6 | BE12: Linaer Blade Twist | BF12: [deg] | BG12: -14 | BI12: =AG12 -> 4.8592659 | BJ12: =AH12 *$BG$8 -> 0.13843 | BK12: =AI12 *$BG$8 -> 0 | BL12: =AM12 * $BG$8 - $BF$3*$BG$8 -> 0.5951855 | BM12: =AN12 * $BG$9/ ($BG$8^2) -> 1.0824769 | BN12: =AO12 * $BG$9 -> 27534492 | BO12: =AP12 * $BG$9*$BG$8^2 -> 482.12886 | BP12: =AQ12 * $BG$8 -> 0.0022606 | BQ12: =AR12 * $BG$8 -> 0.0023114 | BR12: =AS12 * $BG$8 -> 0.016764 | BS12: =AT12 * $BG$8 -> 0.0024638 | BT12: =AU12 * $BG$8 -> -0.000635 | BU12: =AV12 * $BG$8 -> 0.0011938 | BV12: =AW12 * $BG$9*$BG$8^2 -> 740.76804 | BW12: =AX12 * $BG$9*$BG$8^2 -> 11249.673 | BX12: =AY12 * $BG$9*$BG$8^2 -> -200.02608 | BY12: =AZ12 * $BG$9 -> 2.8602065e-05 | BZ12: =BA12 * $BG$9 -> 0.0011698823 | CA12: =BB12 * $BG$9 -> -5.1154549e-06 | CB12: 6
A13: =IF(B13=B12, "same", "") | B13: 0.469 | C13: =B13* $BF$2 -> 31.1885 | D13: 0.000204 | E13: 5780000 | F13: 214000 | G13: 0.033 | H13: 0.113 | I13: -0.04 | J13: 0.055 | K13: -0.051 | L13: 0.078 | M13: 323093 | N13: 3890000 | O13: -51800 | P13: 6.5e-06 | Q13: 0.000343 | R13: -5.59e-06 | S13: 7 | U13: =W13* $BF$2 *$BG$8 - $BF$3 *$BG$8 -> 1.3477302 | V13: 7 | W13: 0.85053 | X13: -1.4 | Y13: 5.45 | Z13: 0 | AA13: 56.56 | AB13: 0 | AC13: 0 | AE13: =_xlfn.XLOOKUP(AL13, $W$7:$W$200, $V$7:$V$200, , -1) -> 3 | AF13: =AE13+1 -> 4 | AG13: =_xlfn.LET( _xlpm.r, $AL13, _xlpm.rp, _xlfn.XLOOKUP($AE13, $V$7:$V$202, $W$7:$W$202, , -1), _xlpm.rn, _xlfn.XLOOKUP($AF13, $V$7:$V$202, $W$7:$W$202, , -1), _xlpm.xp, _xlfn.XLOOKUP($AE13, $V$7:$V$202, X$7:X$202, , -1), _xlpm.xn, _xlfn.XLOOKUP($AF13, $V$7:$V$202, X$7:X$202, , -1), (_xlpm.r - _xlpm.rp)/(_xlpm.rn - _xlpm.rp)*(_xlpm.xn - _xlpm.xp) + _xlpm.xp ) -> 3.9603175 | AH13: =_xlfn.LET( _xlpm.r, $AL13, _xlpm.rp, _xlfn.XLOOKUP($AE13, $V$7:$V$202, $W$7:$W$202, , -1), _xlpm.rn, _xlfn.XLOOKUP($AF13, $V$7:$V$202, $W$7:$W$202, , -1), _xlpm.xp, _xlfn.XLOOKUP($AE13, $V$7:$V$202, Y$7:Y$202, , -1), _xlpm.xn, _xlfn.XLOOKUP($AF13, $V$7:$V$202, Y$7:Y$202, , -1), (_xlpm.r - _xlpm.rp)/(_xlpm.rn - _xlpm.rp)*(_xlpm.xn - _xlpm.xp) + _xlpm.xp ) -> 5.45 | AI13: =- _xlfn.LET( _xlpm.r, $AL13, _xlpm.rp, _xlfn.XLOOKUP($AE13, $V$7:$V$202, $W$7:$W$202, , -1), _xlpm.rn, _xlfn.XLOOKUP($AF13, $V$7:$V$202, $W$7:$W$202, , -1), _xlpm.xp, _xlfn.XLOOKUP($AE13, $V$7:$V$202, AB$7:AB$202, , -1), _xlpm.xn, _xlfn.XLOOKUP($AF13, $V$7:$V$202, AB$7:AB$202, , -1), (_xlpm.r - _xlpm.rp)/(_xlpm.rn - _xlpm.rp)*(_xlpm.xn - _xlpm.xp) + _xlpm.xp ) -> 0 | AJ13: =_xlfn.LET( _xlpm.r, $AL13, _xlpm.rp, _xlfn.XLOOKUP($AE13, $V$7:$V$202, $W$7:$W$202, , -1), _xlpm.rn, _xlfn.XLOOKUP($AF13, $V$7:$V$202, $W$7:$W$202, , -1), _xlpm.xp, _xlfn.XLOOKUP($AE13, $V$7:$V$202, Z$7:Z$202, , -1), _xlpm.xn, _xlfn.XLOOKUP($AF13, $V$7:$V$202, Z$7:Z$202, , -1), (_xlpm.r - _xlpm.rp)/(_xlpm.rn - _xlpm.rp)*(_xlpm.xn - _xlpm.xp) + _xlpm.xp ) -> 0 | AL13: =B13 -> 0.469 | AM13: =C13 -> 31.1885 | AN13: 0.000204 | AO13: 5780000 | AP13: 214000 | AQ13: 0.033 | AR13: 0.113 | AS13: -0.04 | AT13: 0.055 | AU13: -0.051 | AV13: 0.078 | AW13: 323093 | AX13: 3890000 | AY13: -51800 | AZ13: 6.5e-06 | BA13: 0.000343 | BB13: -5.59e-06 | BC13: 7 | BI13: =AG13 -> 3.9603175 | BJ13: =AH13 *$BG$8 -> 0.13843 | BK13: =AI13 *$BG$8 -> 0 | BL13: =AM13 * $BG$8 - $BF$3*$BG$8 -> 0.7032879 | BM13: =AN13 * $BG$9/ ($BG$8^2) -> 1.4065305 | BN13: =AO13 * $BG$9 -> 25710721 | BO13: =AP13 * $BG$9*$BG$8^2 -> 614.14034 | BP13: =AQ13 * $BG$8 -> 0.0008382 | BQ13: =AR13 * $BG$8 -> 0.0028702 | BR13: =AS13 * $BG$8 -> -0.001016 | BS13: =AT13 * $BG$8 -> 0.001397 | BT13: =AU13 * $BG$8 -> -0.0012954 | BU13: =AV13 * $BG$8 -> 0.0019812 | BV13: =AW13 * $BG$9*$BG$8^2 -> 927.21703 | BW13: =AX13 * $BG$9*$BG$8^2 -> 11163.579 | BX13: =AY13 * $BG$9*$BG$8^2 -> -148.6564 | BY13: =AZ13 * $BG$9 -> 2.891344e-05 | BZ13: =BA13 * $BG$9 -> 0.00152574 | CA13: =BB13 * $BG$9 -> -2.4865559e-05 | CB13: 7
A14: =IF(B14=B13, "same", "") | B14: 0.529 | C14: =B14* $BF$2 -> 35.1785 | D14: 0.0002 | E14: 5190000 | F14: 216000 | G14: 0.04 | H14: 0.112 | I14: -0.049 | J14: 0.055 | K14: -0.031 | L14: 0.078 | M14: 296044 | N14: 3600000 | O14: -42300 | P14: 6.5e-06 | Q14: 0.000334 | R14: -5.88e-06 | S14: 8 | U14: 1.5161 | V14: 8 | W14: 0.95023 | X14: -2.8 | Y14: 5.45 | Z14: 0 | AA14: 63.19 | AB14: 0 | AC14: 0 | AE14: =_xlfn.XLOOKUP(AL14, $W$7:$W$200, $V$7:$V$200, , -1) -> 3 | AF14: =AE14+1 -> 4 | AG14: =_xlfn.LET( _xlpm.r, $AL14, _xlpm.rp, _xlfn.XLOOKUP($AE14, $V$7:$V$202, $W$7:$W$202, , -1), _xlpm.rn, _xlfn.XLOOKUP($AF14, $V$7:$V$202, $W$7:$W$202, , -1), _xlpm.xp, _xlfn.XLOOKUP($AE14, $V$7:$V$202, X$7:X$202, , -1), _xlpm.xn, _xlfn.XLOOKUP($AF14, $V$7:$V$202, X$7:X$202, , -1), (_xlpm.r - _xlpm.rp)/(_xlpm.rn - _xlpm.rp)*(_xlpm.xn - _xlpm.xp) + _xlpm.xp ) -> 3.1175533 | AH14: =_xlfn.LET( _xlpm.r, $AL14, _xlpm.rp, _xlfn.XLOOKUP($AE14, $V$7:$V$202, $W$7:$W$202, , -1), _xlpm.rn, _xlfn.XLOOKUP($AF14, $V$7:$V$202, $W$7:$W$202, , -1), _xlpm.xp, _xlfn.XLOOKUP($AE14, $V$7:$V$202, Y$7:Y$202, , -1), _xlpm.xn, _xlfn.XLOOKUP($AF14, $V$7:$V$202, Y$7:Y$202, , -1), (_xlpm.r - _xlpm.rp)/(_xlpm.rn - _xlpm.rp)*(_xlpm.xn - _xlpm.xp) + _xlpm.xp ) -> 5.45 | AI14: =- _xlfn.LET( _xlpm.r, $AL14, _xlpm.rp, _xlfn.XLOOKUP($AE14, $V$7:$V$202, $W$7:$W$202, , -1), _xlpm.rn, _xlfn.XLOOKUP($AF14, $V$7:$V$202, $W$7:$W$202, , -1), _xlpm.xp, _xlfn.XLOOKUP($AE14, $V$7:$V$202, AB$7:AB$202, , -1), _xlpm.xn, _xlfn.XLOOKUP($AF14, $V$7:$V$202, AB$7:AB$202, , -1), (_xlpm.r - _xlpm.rp)/(_xlpm.rn - _xlpm.rp)*(_xlpm.xn - _xlpm.xp) + _xlpm.xp ) -> 0 | AJ14: =_xlfn.LET( _xlpm.r, $AL14, _xlpm.rp, _xlfn.XLOOKUP($AE14, $V$7:$V$202, $W$7:$W$202, , -1), _xlpm.rn, _xlfn.XLOOKUP($AF14, $V$7:$V$202, $W$7:$W$202, , -1), _xlpm.xp, _xlfn.XLOOKUP($AE14, $V$7:$V$202, Z$7:Z$202, , -1), _xlpm.xn, _xlfn.XLOOKUP($AF14, $V$7:$V$202, Z$7:Z$202, , -1), (_xlpm.r - _xlpm.rp)/(_xlpm.rn - _xlpm.rp)*(_xlpm.xn - _xlpm.xp) + _xlpm.xp ) -> 0 | AL14: =B14 -> 0.529 | AM14: =C14 -> 35.1785 | AN14: 0.0002 | AO14: 5190000 | AP14: 216000 | AQ14: 0.04 | AR14: 0.112 | AS14: -0.049 | AT14: 0.055 | AU14: -0.031 | AV14: 0.078 | AW14: 296044 | AX14: 3600000 | AY14: -42300 | AZ14: 6.5e-06 | BA14: 0.000334 | BB14: -5.88e-06 | BC14: 8 | BI14: =AG14 -> 3.1175533 | BJ14: =AH14 *$BG$8 -> 0.13843 | BK14: =AI14 *$BG$8 -> 0 | BL14: =AM14 * $BG$8 - $BF$3*$BG$8 -> 0.8046339 | BM14: =AN14 * $BG$9/ ($BG$8^2) -> 1.3789515 | BN14: =AO14 * $BG$9 -> 23086270 | BO14: =AP14 * $BG$9*$BG$8^2 -> 619.87997 | BP14: =AQ14 * $BG$8 -> 0.001016 | BQ14: =AR14 * $BG$8 -> 0.0028448 | BR14: =AS14 * $BG$8 -> -0.0012446 | BS14: =AT14 * $BG$8 -> 0.001397 | BT14: =AU14 * $BG$8 -> -0.0007874 | BU14: =AV14 * $BG$8 -> 0.0019812 | BV14: =AW14 * $BG$9*$BG$8^2 -> 849.59141 | BW14: =AX14 * $BG$9*$BG$8^2 -> 10331.333 | BX14: =AY14 * $BG$9*$BG$8^2 -> -121.39316 | BY14: =AZ14 * $BG$9 -> 2.891344e-05 | BZ14: =BA14 * $BG$9 -> 0.001485706 | CA14: =BB14 * $BG$9 -> -2.6155543e-05 | CB14: 8
A15: =IF(B15=B14, "same", "") | B15: 0.595 | C15: =B15* $BF$2 -> 39.5675 | D15: 0.000216 | E15: 4730000 | F15: 115000 | G15: 0.118 | H15: 0.114 | I15: -0.055 | J15: 0.069 | K15: 0.086 | L15: 0.084 | M15: 148270 | N15: 2940000 | O15: -7010 | P15: 5.49e-06 | Q15: 0.000374 | R15: -1.85e-06 | S15: 9 | U15: =W15* $BF$2 *$BG$8 - $BF$3 *$BG$8 -> 1.6002 | V15: 9 | W15: 1 | X15: -3.5 | Y15: 3.27 | Z15: 30 | AA15: 66.5 | AB15: -1.911 | AC15: 0 | AE15: =_xlfn.XLOOKUP(AL15, $W$7:$W$200, $V$7:$V$200, , -1) -> 3 | AF15: =AE15+1 -> 4 | AG15: =_xlfn.LET( _xlpm.r, $AL15, _xlpm.rp, _xlfn.XLOOKUP($AE15, $V$7:$V$202, $W$7:$W$202, , -1), _xlpm.rn, _xlfn.XLOOKUP($AF15, $V$7:$V$202, $W$7:$W$202, , -1), _xlpm.xp, _xlfn.XLOOKUP($AE15, $V$7:$V$202, X$7:X$202, , -1), _xlpm.xn, _xlfn.XLOOKUP($AF15, $V$7:$V$202, X$7:X$202, , -1), (_xlpm.r - _xlpm.rp)/(_xlpm.rn - _xlpm.rp)*(_xlpm.xn - _xlpm.xp) + _xlpm.xp ) -> 2.1905128 | AH15: =_xlfn.LET( _xlpm.r, $AL15, _xlpm.rp, _xlfn.XLOOKUP($AE15, $V$7:$V$202, $W$7:$W$202, , -1), _xlpm.rn, _xlfn.XLOOKUP($AF15, $V$7:$V$202, $W$7:$W$202, , -1), _xlpm.xp, _xlfn.XLOOKUP($AE15, $V$7:$V$202, Y$7:Y$202, , -1), _xlpm.xn, _xlfn.XLOOKUP($AF15, $V$7:$V$202, Y$7:Y$202, , -1), (_xlpm.r - _xlpm.rp)/(_xlpm.rn - _xlpm.rp)*(_xlpm.xn - _xlpm.xp) + _xlpm.xp ) -> 5.45 | AI15: =- _xlfn.LET( _xlpm.r, $AL15, _xlpm.rp, _xlfn.XLOOKUP($AE15, $V$7:$V$202, $W$7:$W$202, , -1), _xlpm.rn, _xlfn.XLOOKUP($AF15, $V$7:$V$202, $W$7:$W$202, , -1), _xlpm.xp, _xlfn.XLOOKUP($AE15, $V$7:$V$202, AB$7:AB$202, , -1), _xlpm.xn, _xlfn.XLOOKUP($AF15, $V$7:$V$202, AB$7:AB$202, , -1), (_xlpm.r - _xlpm.rp)/(_xlpm.rn - _xlpm.rp)*(_xlpm.xn - _xlpm.xp) + _xlpm.xp ) -> 0 | AJ15: =_xlfn.LET( _xlpm.r, $AL15, _xlpm.rp, _xlfn.XLOOKUP($AE15, $V$7:$V$202, $W$7:$W$202, , -1), _xlpm.rn, _xlfn.XLOOKUP($AF15, $V$7:$V$202, $W$7:$W$202, , -1), _xlpm.xp, _xlfn.XLOOKUP($AE15, $V$7:$V$202, Z$7:Z$202, , -1), _xlpm.xn, _xlfn.XLOOKUP($AF15, $V$7:$V$202, Z$7:Z$202, , -1), (_xlpm.r - _xlpm.rp)/(_xlpm.rn - _xlpm.rp)*(_xlpm.xn - _xlpm.xp) + _xlpm.xp ) -> 0 | AL15: =B15 -> 0.595 | AM15: =C15 -> 39.5675 | AN15: 0.000216 | AO15: 4730000 | AP15: 115000 | AQ15: 0.118 | AR15: 0.114 | AS15: -0.055 | AT15: 0.069 | AU15: 0.086 | AV15: 0.084 | AW15: 148270 | AX15: 2940000 | AY15: -7010 | AZ15: 5.49e-06 | BA15: 0.000374 | BB15: -1.85e-06 | BC15: 9 | BI15: =AG15 -> 2.1905128 | BJ15: =AH15 *$BG$8 -> 0.13843 | BK15: =AI15 *$BG$8 -> 0 | BL15: =AM15 * $BG$8 - $BF$3*$BG$8 -> 0.9161145 | BM15: =AN15 * $BG$9/ ($BG$8^2) -> 1.4892676 | BN15: =AO15 * $BG$9 -> 21040088 | BO15: =AP15 * $BG$9*$BG$8^2 -> 330.02869 | BP15: =AQ15 * $BG$8 -> 0.0029972 | BQ15: =AR15 * $BG$8 -> 0.0028956 | BR15: =AS15 * $BG$8 -> -0.001397 | BS15: =AT15 * $BG$8 -> 0.0017526 | BT15: =AU15 * $BG$8 -> 0.0021844 | BU15: =AV15 * $BG$8 -> 0.0021336 | BV15: =AW15 * $BG$9*$BG$8^2 -> 425.50742 | BW15: =AX15 * $BG$9*$BG$8^2 -> 8437.2551 | BX15: =AY15 * $BG$9*$BG$8^2 -> -20.117401 | BY15: =AZ15 * $BG$9 -> 2.4420737e-05 | BZ15: =BA15 * $BG$9 -> 0.0016636349 | CA15: =BB15 * $BG$9 -> -8.22921e-06 | CB15: 9
A16: =IF(B16=B15, "same", "") | B16: 0.6 | C16: =B16* $BF$2 -> 39.9 | D16: 0.000219 | E16: 4740000 | F16: 116000 | G16: 0.118 | H16: 0.119 | I16: 0.005 | J16: 0.062 | K16: 0.087 | L16: 0.085 | M16: 148925 | N16: 2940000 | O16: -9080 | P16: 6.83e-06 | Q16: 0.000372 | R16: -1.09e-05 | S16: 10 | AE16: =_xlfn.XLOOKUP(AL16, $W$7:$W$200, $V$7:$V$200, , -1) -> 3 | AF16: =AE16+1 -> 4 | AG16: =_xlfn.LET( _xlpm.r, $AL16, _xlpm.rp, _xlfn.XLOOKUP($AE16, $V$7:$V$202, $W$7:$W$202, , -1), _xlpm.rn, _xlfn.XLOOKUP($AF16, $V$7:$V$202, $W$7:$W$202, , -1), _xlpm.xp, _xlfn.XLOOKUP($AE16, $V$7:$V$202, X$7:X$202, , -1), _xlpm.xn, _xlfn.XLOOKUP($AF16, $V$7:$V$202, X$7:X$202, , -1), (_xlpm.r - _xlpm.rp)/(_xlpm.rn - _xlpm.rp)*(_xlpm.xn - _xlpm.xp) + _xlpm.xp ) -> 2.1202824 | AH16: =_xlfn.LET( _xlpm.r, $AL16, _xlpm.rp, _xlfn.XLOOKUP($AE16, $V$7:$V$202, $W$7:$W$202, , -1), _xlpm.rn, _xlfn.XLOOKUP($AF16, $V$7:$V$202, $W$7:$W$202, , -1), _xlpm.xp, _xlfn.XLOOKUP($AE16, $V$7:$V$202, Y$7:Y$202, , -1), _xlpm.xn, _xlfn.XLOOKUP($AF16, $V$7:$V$202, Y$7:Y$202, , -1), (_xlpm.r - _xlpm.rp)/(_xlpm.rn - _xlpm.rp)*(_xlpm.xn - _xlpm.xp) + _xlpm.xp ) -> 5.45 | AI16: =- _xlfn.LET( _xlpm.r, $AL16, _xlpm.rp, _xlfn.XLOOKUP($AE16, $V$7:$V$202, $W$7:$W$202, , -1), _xlpm.rn, _xlfn.XLOOKUP($AF16, $V$7:$V$202, $W$7:$W$202, , -1), _xlpm.xp, _xlfn.XLOOKUP($AE16, $V$7:$V$202, AB$7:AB$202, , -1), _xlpm.xn, _xlfn.XLOOKUP($AF16, $V$7:$V$202, AB$7:AB$202, , -1), (_xlpm.r - _xlpm.rp)/(_xlpm.rn - _xlpm.rp)*(_xlpm.xn - _xlpm.xp) + _xlpm.xp ) -> 0 | AJ16: =_xlfn.LET( _xlpm.r, $AL16, _xlpm.rp, _xlfn.XLOOKUP($AE16, $V$7:$V$202, $W$7:$W$202, , -1), _xlpm.rn, _xlfn.XLOOKUP($AF16, $V$7:$V$202, $W$7:$W$202, , -1), _xlpm.xp, _xlfn.XLOOKUP($AE16, $V$7:$V$202, Z$7:Z$202, , -1), _xlpm.xn, _xlfn.XLOOKUP($AF16, $V$7:$V$202, Z$7:Z$202, , -1), (_xlpm.r - _xlpm.rp)/(_xlpm.rn - _xlpm.rp)*(_xlpm.xn - _xlpm.xp) + _xlpm.xp ) -> 0 | AL16: =B16 -> 0.6 | AM16: =C16 -> 39.9 | AN16: 0.000219 | AO16: 4740000 | AP16: 116000 | AQ16: 0.118 | AR16: 0.119 | AS16: 0.005 | AT16: 0.062 | AU16: 0.087 | AV16: 0.085 | AW16: 148925 | AX16: 2940000 | AY16: -9080 | AZ16: 6.83e-06 | BA16: 0.000372 | BB16: -1.09e-05 | BC16: 10 | BI16: =AG16 -> 2.1202824 | BJ16: =AH16 *$BG$8 -> 0.13843 | BK16: =AI16 *$BG$8 -> 0 | BL16: =AM16 * $BG$8 - $BF$3*$BG$8 -> 0.92456 | BM16: =AN16 * $BG$9/ ($BG$8^2) -> 1.5099518 | BN16: =AO16 * $BG$9 -> 21084570 | BO16: =AP16 * $BG$9*$BG$8^2 -> 332.8985 | BP16: =AQ16 * $BG$8 -> 0.0029972 | BQ16: =AR16 * $BG$8 -> 0.0030226 | BR16: =AS16 * $BG$8 -> 0.000127 | BS16: =AT16 * $BG$8 -> 0.0015748 | BT16: =AU16 * $BG$8 -> 0.0022098 | BU16: =AV16 * $BG$8 -> 0.002159 | BV16: =AW16 * $BG$9*$BG$8^2 -> 427.38715 | BW16: =AX16 * $BG$9*$BG$8^2 -> 8437.2551 | BX16: =AY16 * $BG$9*$BG$8^2 -> -26.057917 | BY16: =AZ16 * $BG$9 -> 3.0381354e-05 | BZ16: =BA16 * $BG$9 -> 0.0016547384 | CA16: =BB16 * $BG$9 -> -4.8485616e-05 | CB16: 10
A17: =IF(B17=B16, "same", "") | B17: 0.608 | C17: =B17* $BF$2 -> 40.432 | D17: 0.000245 | E17: 4730000 | F17: 115000 | G17: 0.12 | H17: 0.114 | I17: -0.233 | J17: 0.052 | K17: 0.085 | L17: 0.084 | M17: 148135 | N17: 2920000 | O17: -7940 | P17: 6.11e-06 | Q17: 0.000394 | R17: -7.67e-06 | S17: 11 | AE17: =_xlfn.XLOOKUP(AL17, $W$7:$W$200, $V$7:$V$200, , -1) -> 3 | AF17: =AE17+1 -> 4 | AG17: =_xlfn.LET( _xlpm.r, $AL17, _xlpm.rp, _xlfn.XLOOKUP($AE17, $V$7:$V$202, $W$7:$W$202, , -1), _xlpm.rn, _xlfn.XLOOKUP($AF17, $V$7:$V$202, $W$7:$W$202, , -1), _xlpm.xp, _xlfn.XLOOKUP($AE17, $V$7:$V$202, X$7:X$202, , -1), _xlpm.xn, _xlfn.XLOOKUP($AF17, $V$7:$V$202, X$7:X$202, , -1), (_xlpm.r - _xlpm.rp)/(_xlpm.rn - _xlpm.rp)*(_xlpm.xn - _xlpm.xp) + _xlpm.xp ) -> 2.0079139 | AH17: =_xlfn.LET( _xlpm.r, $AL17, _xlpm.rp, _xlfn.XLOOKUP($AE17, $V$7:$V$202, $W$7:$W$202, , -1), _xlpm.rn, _xlfn.XLOOKUP($AF17, $V$7:$V$202, $W$7:$W$202, , -1), _xlpm.xp, _xlfn.XLOOKUP($AE17, $V$7:$V$202, Y$7:Y$202, , -1), _xlpm.xn, _xlfn.XLOOKUP($AF17, $V$7:$V$202, Y$7:Y$202, , -1), (_xlpm.r - _xlpm.rp)/(_xlpm.rn - _xlpm.rp)*(_xlpm.xn - _xlpm.xp) + _xlpm.xp ) -> 5.45 | AI17: =- _xlfn.LET( _xlpm.r, $AL17, _xlpm.rp, _xlfn.XLOOKUP($AE17, $V$7:$V$202, $W$7:$W$202, , -1), _xlpm.rn, _xlfn.XLOOKUP($AF17, $V$7:$V$202, $W$7:$W$202, , -1), _xlpm.xp, _xlfn.XLOOKUP($AE17, $V$7:$V$202, AB$7:AB$202, , -1), _xlpm.xn, _xlfn.XLOOKUP($AF17, $V$7:$V$202, AB$7:AB$202, , -1), (_xlpm.r - _xlpm.rp)/(_xlpm.rn - _xlpm.rp)*(_xlpm.xn - _xlpm.xp) + _xlpm.xp ) -> 0 | AJ17: =_xlfn.LET( _xlpm.r, $AL17, _xlpm.rp, _xlfn.XLOOKUP($AE17, $V$7:$V$202, $W$7:$W$202, , -1), _xlpm.rn, _xlfn.XLOOKUP($AF17, $V$7:$V$202, $W$7:$W$202, , -1), _xlpm.xp, _xlfn.XLOOKUP($AE17, $V$7:$V$202, Z$7:Z$202, , -1), _xlpm.xn, _xlfn.XLOOKUP($AF17, $V$7:$V$202, Z$7:Z$202, , -1), (_xlpm.r - _xlpm.rp)/(_xlpm.rn - _xlpm.rp)*(_xlpm.xn - _xlpm.xp) + _xlpm.xp ) -> 0 | AL17: =B17 -> 0.608 | AM17: =C17 -> 40.432 | AN17: 0.000245 | AO17: 4730000 | AP17: 115000 | AQ17: 0.12 | AR17: 0.114 | AS17: -0.233 | AT17: 0.052 | AU17: 0.085 | AV17: 0.084 | AW17: 148135 | AX17: 2920000 | AY17: -7940 | AZ17: 6.11e-06 | BA17: 0.000394 | BB17: -7.67e-06 | BC17: 11 | BI17: =AG17 -> 2.0079139 | BJ17: =AH17 *$BG$8 -> 0.13843 | BK17: =AI17 *$BG$8 -> 0 | BL17: =AM17 * $BG$8 - $BF$3*$BG$8 -> 0.9380728 | BM17: =AN17 * $BG$9/ ($BG$8^2) -> 1.6892155 | BN17: =AO17 * $BG$9 -> 21040088 | BO17: =AP17 * $BG$9*$BG$8^2 -> 330.02869 | BP17: =AQ17 * $BG$8 -> 0.003048 | BQ17: =AR17 * $BG$8 -> 0.0028956 | BR17: =AS17 * $BG$8 -> -0.0059182 | BS17: =AT17 * $BG$8 -> 0.0013208 | BT17: =AU17 * $BG$8 -> 0.002159 | BU17: =AV17 * $BG$8 -> 0.0021336 | BV17: =AW17 * $BG$9*$BG$8^2 -> 425.11999 | BW17: =AX17 * $BG$9*$BG$8^2 -> 8379.8588 | BX17: =AY17 * $BG$9*$BG$8^2 -> -22.786328 | BY17: =AZ17 * $BG$9 -> 2.7178634e-05 | BZ17: =BA17 * $BG$9 -> 0.0017525993 | CA17: =BB17 * $BG$9 -> -3.411786e-05 | CB17: 11
A18: =IF(B18=B17, "same", "") | B18: 0.676 | C18: =B18* $BF$2 -> 44.954 | D18: 0.000222 | E18: 4480000 | F18: 86100 | G18: 0.15 | H18: 0.112 | I18: -0.277 | J18: 0.048 | K18: 0.126 | L18: 0.085 | M18: 107293 | N18: 2610000 | O18: 5730 | P18: 4.57e-06 | Q18: 0.000342 | R18: -4.17e-06 | S18: 12 | AE18: =_xlfn.XLOOKUP(AL18, $W$7:$W$200, $V$7:$V$200, , -1) -> 4 | AF18: =AE18+1 -> 5 | AG18: =_xlfn.LET( _xlpm.r, $AL18, _xlpm.rp, _xlfn.XLOOKUP($AE18, $V$7:$V$202, $W$7:$W$202, , -1), _xlpm.rn, _xlfn.XLOOKUP($AF18, $V$7:$V$202, $W$7:$W$202, , -1), _xlpm.xp, _xlfn.XLOOKUP($AE18, $V$7:$V$202, X$7:X$202, , -1), _xlpm.xn, _xlfn.XLOOKUP($AF18, $V$7:$V$202, X$7:X$202, , -1), (_xlpm.r - _xlpm.rp)/(_xlpm.rn - _xlpm.rp)*(_xlpm.xn - _xlpm.xp) + _xlpm.xp ) -> 1.0533654 | AH18: =_xlfn.LET( _xlpm.r, $AL18, _xlpm.rp, _xlfn.XLOOKUP($AE18, $V$7:$V$202, $W$7:$W$202, , -1), _xlpm.rn, _xlfn.XLOOKUP($AF18, $V$7:$V$202, $W$7:$W$202, , -1), _xlpm.xp, _xlfn.XLOOKUP($AE18, $V$7:$V$202, Y$7:Y$202, , -1), _xlpm.xn, _xlfn.XLOOKUP($AF18, $V$7:$V$202, Y$7:Y$202, , -1), (_xlpm.r - _xlpm.rp)/(_xlpm.rn - _xlpm.rp)*(_xlpm.xn - _xlpm.xp) + _xlpm.xp ) -> 5.45 | AI18: =- _xlfn.LET( _xlpm.r, $AL18, _xlpm.rp, _xlfn.XLOOKUP($AE18, $V$7:$V$202, $W$7:$W$202, , -1), _xlpm.rn, _xlfn.XLOOKUP($AF18, $V$7:$V$202, $W$7:$W$202, , -1), _xlpm.xp, _xlfn.XLOOKUP($AE18, $V$7:$V$202, AB$7:AB$202, , -1), _xlpm.xn, _xlfn.XLOOKUP($AF18, $V$7:$V$202, AB$7:AB$202, , -1), (_xlpm.r - _xlpm.rp)/(_xlpm.rn - _xlpm.rp)*(_xlpm.xn - _xlpm.xp) + _xlpm.xp ) -> 0 | AJ18: =_xlfn.LET( _xlpm.r, $AL18, _xlpm.rp, _xlfn.XLOOKUP($AE18, $V$7:$V$202, $W$7:$W$202, , -1), _xlpm.rn, _xlfn.XLOOKUP($AF18, $V$7:$V$202, $W$7:$W$202, , -1), _xlpm.xp, _xlfn.XLOOKUP($AE18, $V$7:$V$202, Z$7:Z$202, , -1), _xlpm.xn, _xlfn.XLOOKUP($AF18, $V$7:$V$202, Z$7:Z$202, , -1), (_xlpm.r - _xlpm.rp)/(_xlpm.rn - _xlpm.rp)*(_xlpm.xn - _xlpm.xp) + _xlpm.xp ) -> 0 | AL18: =B18 -> 0.676 | AM18: =C18 -> 44.954 | AN18: =AVERAGE(D18:D20) -> 0.00020166667 | AO18: =AVERAGE(E18:E20) -> 4480000 | AP18: =AVERAGE(F18:F20) -> 86266.667 | AQ18: =AVERAGE(G18:G20) -> 0.15033333 | AR18: =AVERAGE(H18:H20) -> 0.11166667 | AS18: =AVERAGE(I18:I20) -> -0.13533333 | AT18: =AVERAGE(J18:J20) -> 0.055 | AU18: =AVERAGE(K18:K20) -> 0.12666667 | ... BB18: =AVERAGE(R18:R20) -> -3.334e-06 | BC18: 12 | BI18: =AG18 -> 1.0533654 | BJ18: =AH18 *$BG$8 -> 0.13843 | BK18: =AI18 *$BG$8 -> 0 | BL18: =AM18 * $BG$8 - $BF$3*$BG$8 -> 1.0529316 | BM18: =AN18 * $BG$9/ ($BG$8^2) -> 1.3904427 | BN18: =AO18 * $BG$9 -> 19928033 | BO18: =AP18 * $BG$9*$BG$8^2 -> 247.56934 | BP18: =AQ18 * $BG$8 -> 0.0038184667 | BQ18: =AR18 * $BG$8 -> 0.0028363333 | BR18: =AS18 * $BG$8 -> -0.0034374667 | BS18: =AT18 * $BG$8 -> 0.001397 | BT18: =AU18 * $BG$8 -> 0.0032173333 | BU18: =AV18 * $BG$8 -> 0.0021674667 | BV18: =AW18 * $BG$9*$BG$8^2 -> 308.33002 | BW18: =AX18 * $BG$9*$BG$8^2 -> 7518.9144 | BX18: =AY18 * $BG$9*$BG$8^2 -> 17.046699 | BY18: =AZ18 * $BG$9 -> 2.0135617e-05 | BZ18: =BA18 * $BG$9 -> 0.0014708786 | CA18: =BB18 * $BG$9 -> -1.4830371e-05 | CB18: 12
A19: =IF(B19=B18, "same", "") -> same | B19: 0.676 | C19: =B19* $BF$2 -> 44.954 | D19: 0.000193 | E19: 4480000 | F19: 86200 | G19: 0.151 | H19: 0.11 | I19: -0.088 | J19: 0.065 | K19: 0.127 | L19: 0.085 | M19: 107422 | N19: 2620000 | O19: 6540 | P19: 4.06e-06 | Q19: 0.000325 | R19: 8.38e-07 | S19: 13 | AE19: =_xlfn.XLOOKUP(AL19, $W$7:$W$200, $V$7:$V$200, , -1) -> 4 | AF19: =AE19+1 -> 5 | AG19: =_xlfn.LET( _xlpm.r, $AL19, _xlpm.rp, _xlfn.XLOOKUP($AE19, $V$7:$V$202, $W$7:$W$202, , -1), _xlpm.rn, _xlfn.XLOOKUP($AF19, $V$7:$V$202, $W$7:$W$202, , -1), _xlpm.xp, _xlfn.XLOOKUP($AE19, $V$7:$V$202, X$7:X$202, , -1), _xlpm.xn, _xlfn.XLOOKUP($AF19, $V$7:$V$202, X$7:X$202, , -1), (_xlpm.r - _xlpm.rp)/(_xlpm.rn - _xlpm.rp)*(_xlpm.xn - _xlpm.xp) + _xlpm.xp ) -> 0.70280449 | AH19: =_xlfn.LET( _xlpm.r, $AL19, _xlpm.rp, _xlfn.XLOOKUP($AE19, $V$7:$V$202, $W$7:$W$202, , -1), _xlpm.rn, _xlfn.XLOOKUP($AF19, $V$7:$V$202, $W$7:$W$202, , -1), _xlpm.xp, _xlfn.XLOOKUP($AE19, $V$7:$V$202, Y$7:Y$202, , -1), _xlpm.xn, _xlfn.XLOOKUP($AF19, $V$7:$V$202, Y$7:Y$202, , -1), (_xlpm.r - _xlpm.rp)/(_xlpm.rn - _xlpm.rp)*(_xlpm.xn - _xlpm.xp) + _xlpm.xp ) -> 5.45 | AI19: =- _xlfn.LET( _xlpm.r, $AL19, _xlpm.rp, _xlfn.XLOOKUP($AE19, $V$7:$V$202, $W$7:$W$202, , -1), _xlpm.rn, _xlfn.XLOOKUP($AF19, $V$7:$V$202, $W$7:$W$202, , -1), _xlpm.xp, _xlfn.XLOOKUP($AE19, $V$7:$V$202, AB$7:AB$202, , -1), _xlpm.xn, _xlfn.XLOOKUP($AF19, $V$7:$V$202, AB$7:AB$202, , -1), (_xlpm.r - _xlpm.rp)/(_xlpm.rn - _xlpm.rp)*(_xlpm.xn - _xlpm.xp) + _xlpm.xp ) -> 0 | AJ19: =_xlfn.LET( _xlpm.r, $AL19, _xlpm.rp, _xlfn.XLOOKUP($AE19, $V$7:$V$202, $W$7:$W$202, , -1), _xlpm.rn, _xlfn.XLOOKUP($AF19, $V$7:$V$202, $W$7:$W$202, , -1), _xlpm.xp, _xlfn.XLOOKUP($AE19, $V$7:$V$202, Z$7:Z$202, , -1), _xlpm.xn, _xlfn.XLOOKUP($AF19, $V$7:$V$202, Z$7:Z$202, , -1), (_xlpm.r - _xlpm.rp)/(_xlpm.rn - _xlpm.rp)*(_xlpm.xn - _xlpm.xp) + _xlpm.xp ) -> 0 | AL19: =B21 -> 0.701 | AM19: =C21 -> 46.6165 | AN19: 0.000206 | AO19: 4240000 | AP19: 64700 | AQ19: 0.279 | AR19: 0.108 | AS19: -0.264 | AT19: 0.047 | AU19: 0.175 | AV19: 0.087 | AW19: 74230 | AX19: 2370000 | AY19: 11700 | AZ19: 3.53e-06 | BA19: 0.000325 | BB19: -4.04e-06 | BC19: 13 | BI19: =AG19 -> 0.70280449 | BJ19: =AH19 *$BG$8 -> 0.13843 | BK19: =AI19 *$BG$8 -> 0 | BL19: =AM19 * $BG$8 - $BF$3*$BG$8 -> 1.0951591 | BM19: =AN19 * $BG$9/ ($BG$8^2) -> 1.42032 | BN19: =AO19 * $BG$9 -> 18860460 | BO19: =AP19 * $BG$9*$BG$8^2 -> 185.67701 | BP19: =AQ19 * $BG$8 -> 0.0070866 | BQ19: =AR19 * $BG$8 -> 0.0027432 | BR19: =AS19 * $BG$8 -> -0.0067056 | BS19: =AT19 * $BG$8 -> 0.0011938 | BT19: =AU19 * $BG$8 -> 0.004445 | BU19: =AV19 * $BG$8 -> 0.0022098 | BV19: =AW19 * $BG$9*$BG$8^2 -> 213.02634 | BW19: =AX19 * $BG$9*$BG$8^2 -> 6801.4607 | BX19: =AY19 * $BG$9*$BG$8^2 -> 33.576831 | BY19: =AZ19 * $BG$9 -> 1.5702222e-05 | BZ19: =BA19 * $BG$9 -> 0.001445672 | CA19: =BB19 * $BG$9 -> -1.7970815e-05 | CB19: 13
A20: =IF(B20=B19, "same", "") -> same | B20: 0.676 | C20: =B20* $BF$2 -> 44.954 | D20: 0.00019 | E20: 4480000 | F20: 86500 | G20: 0.15 | H20: 0.113 | I20: -0.041 | J20: 0.052 | K20: 0.127 | L20: 0.086 | M20: 107602 | N20: 2630000 | O20: 5550 | P20: 4.95e-06 | Q20: 0.000325 | R20: -6.67e-06 | S20: 14 | AE20: =_xlfn.XLOOKUP(AL20, $W$7:$W$200, $V$7:$V$200, , -1) -> 5 | AF20: =AE20+1 -> 6 | AG20: =_xlfn.LET( _xlpm.r, $AL20, _xlpm.rp, _xlfn.XLOOKUP($AE20, $V$7:$V$202, $W$7:$W$202, , -1), _xlpm.rn, _xlfn.XLOOKUP($AF20, $V$7:$V$202, $W$7:$W$202, , -1), _xlpm.xp, _xlfn.XLOOKUP($AE20, $V$7:$V$202, X$7:X$202, , -1), _xlpm.xn, _xlfn.XLOOKUP($AF20, $V$7:$V$202, X$7:X$202, , -1), (_xlpm.r - _xlpm.rp)/(_xlpm.rn - _xlpm.rp)*(_xlpm.xn - _xlpm.xp) + _xlpm.xp ) -> 0.084028127 | AH20: =_xlfn.LET( _xlpm.r, $AL20, _xlpm.rp, _xlfn.XLOOKUP($AE20, $V$7:$V$202, $W$7:$W$202, , -1), _xlpm.rn, _xlfn.XLOOKUP($AF20, $V$7:$V$202, $W$7:$W$202, , -1), _xlpm.xp, _xlfn.XLOOKUP($AE20, $V$7:$V$202, Y$7:Y$202, , -1), _xlpm.xn, _xlfn.XLOOKUP($AF20, $V$7:$V$202, Y$7:Y$202, , -1), (_xlpm.r - _xlpm.rp)/(_xlpm.rn - _xlpm.rp)*(_xlpm.xn - _xlpm.xp) + _xlpm.xp ) -> 5.45 | AI20: =- _xlfn.LET( _xlpm.r, $AL20, _xlpm.rp, _xlfn.XLOOKUP($AE20, $V$7:$V$202, $W$7:$W$202, , -1), _xlpm.rn, _xlfn.XLOOKUP($AF20, $V$7:$V$202, $W$7:$W$202, , -1), _xlpm.xp, _xlfn.XLOOKUP($AE20, $V$7:$V$202, AB$7:AB$202, , -1), _xlpm.xn, _xlfn.XLOOKUP($AF20, $V$7:$V$202, AB$7:AB$202, , -1), (_xlpm.r - _xlpm.rp)/(_xlpm.rn - _xlpm.rp)*(_xlpm.xn - _xlpm.xp) + _xlpm.xp ) -> 0 | AJ20: =_xlfn.LET( _xlpm.r, $AL20, _xlpm.rp, _xlfn.XLOOKUP($AE20, $V$7:$V$202, $W$7:$W$202, , -1), _xlpm.rn, _xlfn.XLOOKUP($AF20, $V$7:$V$202, $W$7:$W$202, , -1), _xlpm.xp, _xlfn.XLOOKUP($AE20, $V$7:$V$202, Z$7:Z$202, , -1), _xlpm.xn, _xlfn.XLOOKUP($AF20, $V$7:$V$202, Z$7:Z$202, , -1), (_xlpm.r - _xlpm.rp)/(_xlpm.rn - _xlpm.rp)*(_xlpm.xn - _xlpm.xp) + _xlpm.xp ) -> 0 | AL20: =B22 -> 0.745 | AM20: =C22 -> 49.5425 | AN20: 0.000179 | AO20: 4240000 | AP20: 64700 | AQ20: 0.281 | AR20: 0.108 | AS20: -0.035 | AT20: 0.065 | AU20: 0.176 | AV20: 0.087 | AW20: 74337 | AX20: 2380000 | AY20: 12400 | AZ20: 3.1e-06 | BA20: 0.000306 | BB20: 6.76e-07 | BC20: 14 | BI20: =AG20 -> 0.084028127 | BJ20: =AH20 *$BG$8 -> 0.13843 | BK20: =AI20 *$BG$8 -> 0 | BL20: =AM20 * $BG$8 - $BF$3*$BG$8 -> 1.1694795 | BM20: =AN20 * $BG$9/ ($BG$8^2) -> 1.2341616 | BN20: =AO20 * $BG$9 -> 18860460 | BO20: =AP20 * $BG$9*$BG$8^2 -> 185.67701 | BP20: =AQ20 * $BG$8 -> 0.0071374 | BQ20: =AR20 * $BG$8 -> 0.0027432 | BR20: =AS20 * $BG$8 -> -0.000889 | BS20: =AT20 * $BG$8 -> 0.001651 | BT20: =AU20 * $BG$8 -> 0.0044704 | BU20: =AV20 * $BG$8 -> 0.0022098 | BV20: =AW20 * $BG$9*$BG$8^2 -> 213.33341 | BW20: =AX20 * $BG$9*$BG$8^2 -> 6830.1589 | BX20: =AY20 * $BG$9*$BG$8^2 -> 35.585702 | BY20: =AZ20 * $BG$9 -> 1.3789487e-05 | BZ20: =BA20 * $BG$9 -> 0.0013611558 | CA20: =BB20 * $BG$9 -> 3.0069978e-06 | CB20: 14
A21: =IF(B21=B20, "same", "") | B21: 0.701 | C21: =B21* $BF$2 -> 46.6165 | D21: 0.000206 | E21: 4240000 | F21: 64700 | G21: 0.279 | H21: 0.108 | I21: -0.264 | J21: 0.047 | K21: 0.175 | L21: 0.087 | M21: 74230 | N21: 2370000 | O21: 11700 | P21: 3.53e-06 | Q21: 0.000325 | R21: -4.04e-06 | S21: 15 | AE21: =_xlfn.XLOOKUP(AL21, $W$7:$W$200, $V$7:$V$200, , -1) -> 5 | AF21: =AE21+1 -> 6 | AG21: =_xlfn.LET( _xlpm.r, $AL21, _xlpm.rp, _xlfn.XLOOKUP($AE21, $V$7:$V$202, $W$7:$W$202, , -1), _xlpm.rn, _xlfn.XLOOKUP($AF21, $V$7:$V$202, $W$7:$W$202, , -1), _xlpm.xp, _xlfn.XLOOKUP($AE21, $V$7:$V$202, X$7:X$202, , -1), _xlpm.xn, _xlfn.XLOOKUP($AF21, $V$7:$V$202, X$7:X$202, , -1), (_xlpm.r - _xlpm.rp)/(_xlpm.rn - _xlpm.rp)*(_xlpm.xn - _xlpm.xp) + _xlpm.xp ) -> 0.013711703 | AH21: =_xlfn.LET( _xlpm.r, $AL21, _xlpm.rp, _xlfn.XLOOKUP($AE21, $V$7:$V$202, $W$7:$W$202, , -1), _xlpm.rn, _xlfn.XLOOKUP($AF21, $V$7:$V$202, $W$7:$W$202, , -1), _xlpm.xp, _xlfn.XLOOKUP($AE21, $V$7:$V$202, Y$7:Y$202, , -1), _xlpm.xn, _xlfn.XLOOKUP($AF21, $V$7:$V$202, Y$7:Y$202, , -1), (_xlpm.r - _xlpm.rp)/(_xlpm.rn - _xlpm.rp)*(_xlpm.xn - _xlpm.xp) + _xlpm.xp ) -> 5.45 | AI21: =- _xlfn.LET( _xlpm.r, $AL21, _xlpm.rp, _xlfn.XLOOKUP($AE21, $V$7:$V$202, $W$7:$W$202, , -1), _xlpm.rn, _xlfn.XLOOKUP($AF21, $V$7:$V$202, $W$7:$W$202, , -1), _xlpm.xp, _xlfn.XLOOKUP($AE21, $V$7:$V$202, AB$7:AB$202, , -1), _xlpm.xn, _xlfn.XLOOKUP($AF21, $V$7:$V$202, AB$7:AB$202, , -1), (_xlpm.r - _xlpm.rp)/(_xlpm.rn - _xlpm.rp)*(_xlpm.xn - _xlpm.xp) + _xlpm.xp ) -> 0 | AJ21: =_xlfn.LET( _xlpm.r, $AL21, _xlpm.rp, _xlfn.XLOOKUP($AE21, $V$7:$V$202, $W$7:$W$202, , -1), _xlpm.rn, _xlfn.XLOOKUP($AF21, $V$7:$V$202, $W$7:$W$202, , -1), _xlpm.xp, _xlfn.XLOOKUP($AE21, $V$7:$V$202, Z$7:Z$202, , -1), _xlpm.xn, _xlfn.XLOOKUP($AF21, $V$7:$V$202, Z$7:Z$202, , -1), (_xlpm.r - _xlpm.rp)/(_xlpm.rn - _xlpm.rp)*(_xlpm.xn - _xlpm.xp) + _xlpm.xp ) -> 0 | AL21: =B23 -> 0.75 | AM21: =C23 -> 49.875 | AN21: 0.000177 | AO21: 4250000 | AP21: 65000 | AQ21: 0.28 | AR21: 0.11 | AS21: 0.012 | AT21: 0.053 | AU21: 0.176 | AV21: 0.087 | AW21: 74471 | AX21: 2380000 | AY21: 11600 | AZ21: 3.68e-06 | BA21: 0.0003 | BB21: -4.93e-06 | BC21: 15 | BI21: =AG21 -> 0.013711703 | BJ21: =AH21 *$BG$8 -> 0.13843 | BK21: =AI21 *$BG$8 -> 0 | BL21: =AM21 * $BG$8 - $BF$3*$BG$8 -> 1.177925 | BM21: =AN21 * $BG$9/ ($BG$8^2) -> 1.220372 | BN21: =AO21 * $BG$9 -> 18904942 | BO21: =AP21 * $BG$9*$BG$8^2 -> 186.53795 | BP21: =AQ21 * $BG$8 -> 0.007112 | BQ21: =AR21 * $BG$8 -> 0.002794 | BR21: =AS21 * $BG$8 -> 0.0003048 | BS21: =AT21 * $BG$8 -> 0.0013462 | BT21: =AU21 * $BG$8 -> 0.0044704 | BU21: =AV21 * $BG$8 -> 0.0022098 | BV21: =AW21 * $BG$9*$BG$8^2 -> 213.71797 | BW21: =AX21 * $BG$9*$BG$8^2 -> 6830.1589 | BX21: =AY21 * $BG$9*$BG$8^2 -> 33.28985 | BY21: =AZ21 * $BG$9 -> 1.6369456e-05 | BZ21: =BA21 * $BG$9 -> 0.0013344665 | CA21: =BB21 * $BG$9 -> -2.1929733e-05 | CB21: 15
A22: =IF(B22=B21, "same", "") | B22: 0.745 | C22: =B22* $BF$2 -> 49.5425 | D22: 0.000179 | E22: 4240000 | F22: 64700 | G22: 0.281 | H22: 0.108 | I22: -0.035 | J22: 0.065 | K22: 0.176 | L22: 0.087 | M22: 74337 | N22: 2380000 | O22: 12400 | P22: 3.1e-06 | Q22: 0.000306 | R22: 6.76e-07 | S22: 16 | AE22: =_xlfn.XLOOKUP(AL22, $W$7:$W$200, $V$7:$V$200, , -1) -> 6 | AF22: =AE22+1 -> 7 | AG22: =_xlfn.LET( _xlpm.r, $AL22, _xlpm.rp, _xlfn.XLOOKUP($AE22, $V$7:$V$202, $W$7:$W$202, , -1), _xlpm.rn, _xlfn.XLOOKUP($AF22, $V$7:$V$202, $W$7:$W$202, , -1), _xlpm.xp, _xlfn.XLOOKUP($AE22, $V$7:$V$202, X$7:X$202, , -1), _xlpm.xn, _xlfn.XLOOKUP($AF22, $V$7:$V$202, X$7:X$202, , -1), (_xlpm.r - _xlpm.rp)/(_xlpm.rn - _xlpm.rp)*(_xlpm.xn - _xlpm.xp) + _xlpm.xp ) -> -1.0550623 | AH22: =_xlfn.LET( _xlpm.r, $AL22, _xlpm.rp, _xlfn.XLOOKUP($AE22, $V$7:$V$202, $W$7:$W$202, , -1), _xlpm.rn, _xlfn.XLOOKUP($AF22, $V$7:$V$202, $W$7:$W$202, , -1), _xlpm.xp, _xlfn.XLOOKUP($AE22, $V$7:$V$202, Y$7:Y$202, , -1), _xlpm.xn, _xlfn.XLOOKUP($AF22, $V$7:$V$202, Y$7:Y$202, , -1), (_xlpm.r - _xlpm.rp)/(_xlpm.rn - _xlpm.rp)*(_xlpm.xn - _xlpm.xp) + _xlpm.xp ) -> 5.45 | AI22: =- _xlfn.LET( _xlpm.r, $AL22, _xlpm.rp, _xlfn.XLOOKUP($AE22, $V$7:$V$202, $W$7:$W$202, , -1), _xlpm.rn, _xlfn.XLOOKUP($AF22, $V$7:$V$202, $W$7:$W$202, , -1), _xlpm.xp, _xlfn.XLOOKUP($AE22, $V$7:$V$202, AB$7:AB$202, , -1), _xlpm.xn, _xlfn.XLOOKUP($AF22, $V$7:$V$202, AB$7:AB$202, , -1), (_xlpm.r - _xlpm.rp)/(_xlpm.rn - _xlpm.rp)*(_xlpm.xn - _xlpm.xp) + _xlpm.xp ) -> 0 | AJ22: =_xlfn.LET( _xlpm.r, $AL22, _xlpm.rp, _xlfn.XLOOKUP($AE22, $V$7:$V$202, $W$7:$W$202, , -1), _xlpm.rn, _xlfn.XLOOKUP($AF22, $V$7:$V$202, $W$7:$W$202, , -1), _xlpm.xp, _xlfn.XLOOKUP($AE22, $V$7:$V$202, Z$7:Z$202, , -1), _xlpm.xn, _xlfn.XLOOKUP($AF22, $V$7:$V$202, Z$7:Z$202, , -1), (_xlpm.r - _xlpm.rp)/(_xlpm.rn - _xlpm.rp)*(_xlpm.xn - _xlpm.xp) + _xlpm.xp ) -> 0 | AL22: =B24 -> 0.826 | AM22: =C24 -> 54.929 | AN22: =AVERAGE(D24:D26) -> 0.000191 | AO22: =AVERAGE(E24:E26) -> 3673333.3 | AP22: =AVERAGE(F24:F26) -> 42133.333 | AQ22: =AVERAGE(G24:G26) -> 0.21933333 | AR22: =AVERAGE(H24:H26) -> 0.078333333 | AS22: =AVERAGE(I24:I26) -> -0.15866667 | AT22: =AVERAGE(J24:J26) -> 0.039666667 | AU22: =AVERAGE(K24:K26) -> 0.21866667 | ... BB22: =AVERAGE(R24:R26) -> -1.41e-06 | BC22: 16 | BI22: =AG22 -> -1.0550623 | BJ22: =AH22 *$BG$8 -> 0.13843 | BK22: =AI22 *$BG$8 -> 0 | BL22: =AM22 * $BG$8 - $BF$3*$BG$8 -> 1.3062966 | BM22: =AN22 * $BG$9/ ($BG$8^2) -> 1.3168986 | BN22: =AO22 * $BG$9 -> 16339801 | BO22: =AP22 * $BG$9*$BG$8^2 -> 120.91486 | BP22: =AQ22 * $BG$8 -> 0.0055710667 | BQ22: =AR22 * $BG$8 -> 0.0019896667 | BR22: =AS22 * $BG$8 -> -0.0040301333 | BS22: =AT22 * $BG$8 -> 0.0010075333 | BT22: =AU22 * $BG$8 -> 0.0055541333 | BU22: =AV22 * $BG$8 -> 0.0015494 | BV22: =AW22 * $BG$9*$BG$8^2 -> 128.32472 | BW22: =AX22 * $BG$9*$BG$8^2 -> 6112.7052 | BX22: =AY22 * $BG$9*$BG$8^2 -> 31.950603 | BY22: =AZ22 * $BG$9 -> 1.0601595e-05 | BZ22: =BA22 * $BG$9 -> 0.0013522594 | CA22: =BB22 * $BG$9 -> -6.2719925e-06 | CB22: 16
A23: =IF(B23=B22, "same", "") | B23: 0.75 | C23: =B23* $BF$2 -> 49.875 | D23: 0.000177 | E23: 4250000 | F23: 65000 | G23: 0.28 | H23: 0.11 | I23: 0.012 | J23: 0.053 | K23: 0.176 | L23: 0.087 | M23: 74471 | N23: 2380000 | O23: 11600 | P23: 3.68e-06 | Q23: 0.0003 | R23: -4.93e-06 | S23: 17 | AE23: =_xlfn.XLOOKUP(AL23, $W$7:$W$200, $V$7:$V$200, , -1) -> 7 | AF23: =AE23+1 -> 8 | AG23: =_xlfn.LET( _xlpm.r, $AL23, _xlpm.rp, _xlfn.XLOOKUP($AE23, $V$7:$V$202, $W$7:$W$202, , -1), _xlpm.rn, _xlfn.XLOOKUP($AF23, $V$7:$V$202, $W$7:$W$202, , -1), _xlpm.xp, _xlfn.XLOOKUP($AE23, $V$7:$V$202, X$7:X$202, , -1), _xlpm.xn, _xlfn.XLOOKUP($AF23, $V$7:$V$202, X$7:X$202, , -1), (_xlpm.r - _xlpm.rp)/(_xlpm.rn - _xlpm.rp)*(_xlpm.xn - _xlpm.xp) + _xlpm.xp ) -> -1.4065998 | AH23: =_xlfn.LET( _xlpm.r, $AL23, _xlpm.rp, _xlfn.XLOOKUP($AE23, $V$7:$V$202, $W$7:$W$202, , -1), _xlpm.rn, _xlfn.XLOOKUP($AF23, $V$7:$V$202, $W$7:$W$202, , -1), _xlpm.xp, _xlfn.XLOOKUP($AE23, $V$7:$V$202, Y$7:Y$202, , -1), _xlpm.xn, _xlfn.XLOOKUP($AF23, $V$7:$V$202, Y$7:Y$202, , -1), (_xlpm.r - _xlpm.rp)/(_xlpm.rn - _xlpm.rp)*(_xlpm.xn - _xlpm.xp) + _xlpm.xp ) -> 5.45 | AI23: =- _xlfn.LET( _xlpm.r, $AL23, _xlpm.rp, _xlfn.XLOOKUP($AE23, $V$7:$V$202, $W$7:$W$202, , -1), _xlpm.rn, _xlfn.XLOOKUP($AF23, $V$7:$V$202, $W$7:$W$202, , -1), _xlpm.xp, _xlfn.XLOOKUP($AE23, $V$7:$V$202, AB$7:AB$202, , -1), _xlpm.xn, _xlfn.XLOOKUP($AF23, $V$7:$V$202, AB$7:AB$202, , -1), (_xlpm.r - _xlpm.rp)/(_xlpm.rn - _xlpm.rp)*(_xlpm.xn - _xlpm.xp) + _xlpm.xp ) -> 0 | AJ23: =_xlfn.LET( _xlpm.r, $AL23, _xlpm.rp, _xlfn.XLOOKUP($AE23, $V$7:$V$202, $W$7:$W$202, , -1), _xlpm.rn, _xlfn.XLOOKUP($AF23, $V$7:$V$202, $W$7:$W$202, , -1), _xlpm.xp, _xlfn.XLOOKUP($AE23, $V$7:$V$202, Z$7:Z$202, , -1), _xlpm.xn, _xlfn.XLOOKUP($AF23, $V$7:$V$202, Z$7:Z$202, , -1), (_xlpm.r - _xlpm.rp)/(_xlpm.rn - _xlpm.rp)*(_xlpm.xn - _xlpm.xp) + _xlpm.xp ) -> 0 | AL23: =B27 -> 0.851 | AM23: =C27 -> 56.5915 | AN23: 0.000212 | AO23: 3110000 | AP23: 27300 | AQ23: 0.315 | AR23: 0.061 | AS23: -0.336 | AT23: 0.023 | AU23: 0.26 | AV23: 0.035 | AW23: 24143 | AX23: 1890000 | AY23: 7400 | AZ23: 1.63e-06 | BA23: 0.000301 | BB23: -5.93e-07 | BC23: 17 | BI23: =AG23 -> -1.4065998 | BJ23: =AH23 *$BG$8 -> 0.13843 | BK23: =AI23 *$BG$8 -> 0 | BL23: =AM23 * $BG$8 - $BF$3*$BG$8 -> 1.3485241 | BM23: =AN23 * $BG$9/ ($BG$8^2) -> 1.4616885 | BN23: =AO23 * $BG$9 -> 13833969 | BO23: =AP23 * $BG$9*$BG$8^2 -> 78.34594 | BP23: =AQ23 * $BG$8 -> 0.008001 | BQ23: =AR23 * $BG$8 -> 0.0015494 | BR23: =AS23 * $BG$8 -> -0.0085344 | BS23: =AT23 * $BG$8 -> 0.0005842 | BT23: =AU23 * $BG$8 -> 0.006604 | BU23: =AV23 * $BG$8 -> 0.000889 | BV23: =AW23 * $BG$9*$BG$8^2 -> 69.285935 | BW23: =AX23 * $BG$9*$BG$8^2 -> 5423.9497 | BX23: =AY23 * $BG$9*$BG$8^2 -> 21.236628 | BY23: =AZ23 * $BG$9 -> 7.2506012e-06 | BZ23: =BA23 * $BG$9 -> 0.0013389147 | CA23: =BB23 * $BG$9 -> -2.6377954e-06 | CB23: 17
A24: =IF(B24=B23, "same", "") | B24: 0.826 | C24: =B24* $BF$2 -> 54.929 | D24: 0.000214 | E24: 3670000 | F24: 42000 | G24: 0.218 | H24: 0.078 | I24: -0.316 | J24: 0.034 | K24: 0.218 | L24: 0.061 | M24: 44624 | N24: 2120000 | O24: 11000 | P24: 2.48e-06 | Q24: 0.000317 | R24: -2.16e-06 | S24: 18 | AE24: =_xlfn.XLOOKUP(AL24, $W$7:$W$200, $V$7:$V$200, , -1) -> 7 | AF24: =AE24+1 -> 8 | AG24: =_xlfn.LET( _xlpm.r, $AL24, _xlpm.rp, _xlfn.XLOOKUP($AE24, $V$7:$V$202, $W$7:$W$202, , -1), _xlpm.rn, _xlfn.XLOOKUP($AF24, $V$7:$V$202, $W$7:$W$202, , -1), _xlpm.xp, _xlfn.XLOOKUP($AE24, $V$7:$V$202, X$7:X$202, , -1), _xlpm.xn, _xlfn.XLOOKUP($AF24, $V$7:$V$202, X$7:X$202, , -1), (_xlpm.r - _xlpm.rp)/(_xlpm.rn - _xlpm.rp)*(_xlpm.xn - _xlpm.xp) + _xlpm.xp ) -> -2.4457172 | AH24: =_xlfn.LET( _xlpm.r, $AL24, _xlpm.rp, _xlfn.XLOOKUP($AE24, $V$7:$V$202, $W$7:$W$202, , -1), _xlpm.rn, _xlfn.XLOOKUP($AF24, $V$7:$V$202, $W$7:$W$202, , -1), _xlpm.xp, _xlfn.XLOOKUP($AE24, $V$7:$V$202, Y$7:Y$202, , -1), _xlpm.xn, _xlfn.XLOOKUP($AF24, $V$7:$V$202, Y$7:Y$202, , -1), (_xlpm.r - _xlpm.rp)/(_xlpm.rn - _xlpm.rp)*(_xlpm.xn - _xlpm.xp) + _xlpm.xp ) -> 5.45 | AI24: =- _xlfn.LET( _xlpm.r, $AL24, _xlpm.rp, _xlfn.XLOOKUP($AE24, $V$7:$V$202, $W$7:$W$202, , -1), _xlpm.rn, _xlfn.XLOOKUP($AF24, $V$7:$V$202, $W$7:$W$202, , -1), _xlpm.xp, _xlfn.XLOOKUP($AE24, $V$7:$V$202, AB$7:AB$202, , -1), _xlpm.xn, _xlfn.XLOOKUP($AF24, $V$7:$V$202, AB$7:AB$202, , -1), (_xlpm.r - _xlpm.rp)/(_xlpm.rn - _xlpm.rp)*(_xlpm.xn - _xlpm.xp) + _xlpm.xp ) -> 0 | AJ24: =_xlfn.LET( _xlpm.r, $AL24, _xlpm.rp, _xlfn.XLOOKUP($AE24, $V$7:$V$202, $W$7:$W$202, , -1), _xlpm.rn, _xlfn.XLOOKUP($AF24, $V$7:$V$202, $W$7:$W$202, , -1), _xlpm.xp, _xlfn.XLOOKUP($AE24, $V$7:$V$202, Z$7:Z$202, , -1), _xlpm.xn, _xlfn.XLOOKUP($AF24, $V$7:$V$202, Z$7:Z$202, , -1), (_xlpm.r - _xlpm.rp)/(_xlpm.rn - _xlpm.rp)*(_xlpm.xn - _xlpm.xp) + _xlpm.xp ) -> 0 | AL24: =B28 -> 0.925 | AM24: =C28 -> 61.5125 | AN24: 0.000171 | AO24: 3110000 | AP24: 27300 | AQ24: 0.317 | AR24: 0.06 | AS24: -0.094 | AT24: 0.038 | AU24: 0.261 | AV24: 0.035 | AW24: 24198 | AX24: 1900000 | AY24: 7820 | AZ24: 1.42e-06 | BA24: 0.00028 | BB24: 2.82e-06 | BC24: 18 | BI24: =AG24 -> -2.4457172 | BJ24: =AH24 *$BG$8 -> 0.13843 | BK24: =AI24 *$BG$8 -> 0 | BL24: =AM24 * $BG$8 - $BF$3*$BG$8 -> 1.4735175 | BM24: =AN24 * $BG$9/ ($BG$8^2) -> 1.1790035 | BN24: =AO24 * $BG$9 -> 13833969 | BO24: =AP24 * $BG$9*$BG$8^2 -> 78.34594 | BP24: =AQ24 * $BG$8 -> 0.0080518 | BQ24: =AR24 * $BG$8 -> 0.001524 | BR24: =AS24 * $BG$8 -> -0.0023876 | BS24: =AT24 * $BG$8 -> 0.0009652 | BT24: =AU24 * $BG$8 -> 0.0066294 | BU24: =AV24 * $BG$8 -> 0.000889 | BV24: =AW24 * $BG$9*$BG$8^2 -> 69.443775 | BW24: =AX24 * $BG$9*$BG$8^2 -> 5452.6478 | BX24: =AY24 * $BG$9*$BG$8^2 -> 22.441951 | BY24: =AZ24 * $BG$9 -> 6.3164747e-06 | BZ24: =BA24 * $BG$9 -> 0.0012455021 | CA24: =BB24 * $BG$9 -> 1.2543985e-05 | CB24: 18
A25: =IF(B25=B24, "same", "") -> same | B25: 0.826 | C25: =B25* $BF$2 -> 54.929 | D25: 0.000179 | E25: 3670000 | F25: 42100 | G25: 0.22 | H25: 0.077 | I25: -0.096 | J25: 0.051 | K25: 0.219 | L25: 0.061 | M25: 44702 | N25: 2130000 | O25: 11500 | P25: 2.14e-06 | Q25: 0.000298 | R25: 1.96e-06 | S25: 19 | AE25: =_xlfn.XLOOKUP(AL25, $W$7:$W$200, $V$7:$V$200, , -1) -> 7 | AF25: =AE25+1 -> 8 | AG25: =_xlfn.LET( _xlpm.r, $AL25, _xlpm.rp, _xlfn.XLOOKUP($AE25, $V$7:$V$202, $W$7:$W$202, , -1), _xlpm.rn, _xlfn.XLOOKUP($AF25, $V$7:$V$202, $W$7:$W$202, , -1), _xlpm.xp, _xlfn.XLOOKUP($AE25, $V$7:$V$202, X$7:X$202, , -1), _xlpm.xn, _xlfn.XLOOKUP($AF25, $V$7:$V$202, X$7:X$202, , -1), (_xlpm.r - _xlpm.rp)/(_xlpm.rn - _xlpm.rp)*(_xlpm.xn - _xlpm.xp) + _xlpm.xp ) -> -2.3755065 | AH25: =_xlfn.LET( _xlpm.r, $AL25, _xlpm.rp, _xlfn.XLOOKUP($AE25, $V$7:$V$202, $W$7:$W$202, , -1), _xlpm.rn, _xlfn.XLOOKUP($AF25, $V$7:$V$202, $W$7:$W$202, , -1), _xlpm.xp, _xlfn.XLOOKUP($AE25, $V$7:$V$202, Y$7:Y$202, , -1), _xlpm.xn, _xlfn.XLOOKUP($AF25, $V$7:$V$202, Y$7:Y$202, , -1), (_xlpm.r - _xlpm.rp)/(_xlpm.rn - _xlpm.rp)*(_xlpm.xn - _xlpm.xp) + _xlpm.xp ) -> 5.45 | AI25: =- _xlfn.LET( _xlpm.r, $AL25, _xlpm.rp, _xlfn.XLOOKUP($AE25, $V$7:$V$202, $W$7:$W$202, , -1), _xlpm.rn, _xlfn.XLOOKUP($AF25, $V$7:$V$202, $W$7:$W$202, , -1), _xlpm.xp, _xlfn.XLOOKUP($AE25, $V$7:$V$202, AB$7:AB$202, , -1), _xlpm.xn, _xlfn.XLOOKUP($AF25, $V$7:$V$202, AB$7:AB$202, , -1), (_xlpm.r - _xlpm.rp)/(_xlpm.rn - _xlpm.rp)*(_xlpm.xn - _xlpm.xp) + _xlpm.xp ) -> 0 | AJ25: =_xlfn.LET( _xlpm.r, $AL25, _xlpm.rp, _xlfn.XLOOKUP($AE25, $V$7:$V$202, $W$7:$W$202, , -1), _xlpm.rn, _xlfn.XLOOKUP($AF25, $V$7:$V$202, $W$7:$W$202, , -1), _xlpm.xp, _xlfn.XLOOKUP($AE25, $V$7:$V$202, Z$7:Z$202, , -1), _xlpm.xn, _xlfn.XLOOKUP($AF25, $V$7:$V$202, Z$7:Z$202, , -1), (_xlpm.r - _xlpm.rp)/(_xlpm.rn - _xlpm.rp)*(_xlpm.xn - _xlpm.xp) + _xlpm.xp ) -> 0 | AL25: =B29 -> 0.92 | AM25: =C29 -> 61.18 | AN25: 0.000184 | AO25: 3130000 | AP25: 27500 | AQ25: 0.323 | AR25: 0.055 | AS25: 0.025 | AT25: 0.029 | AU25: 0.267 | AV25: 0.034 | AW25: 24427 | AX25: 1930000 | AY25: 9770 | AZ25: 1.65e-06 | BA25: 0.000322 | BB25: 5.29e-06 | BC25: 19 | BI25: =AG25 -> -2.3755065 | BJ25: =AH25 *$BG$8 -> 0.13843 | BK25: =AI25 *$BG$8 -> 0 | BL25: =AM25 * $BG$8 - $BF$3*$BG$8 -> 1.465072 | BM25: =AN25 * $BG$9/ ($BG$8^2) -> 1.2686353 | BN25: =AO25 * $BG$9 -> 13922934 | BO25: =AP25 * $BG$9*$BG$8^2 -> 78.919903 | BP25: =AQ25 * $BG$8 -> 0.0082042 | BQ25: =AR25 * $BG$8 -> 0.001397 | BR25: =AS25 * $BG$8 -> 0.000635 | BS25: =AT25 * $BG$8 -> 0.0007366 | BT25: =AU25 * $BG$8 -> 0.0067818 | BU25: =AV25 * $BG$8 -> 0.0008636 | BV25: =AW25 * $BG$9*$BG$8^2 -> 70.100963 | BW25: =AX25 * $BG$9*$BG$8^2 -> 5538.7423 | BX25: =AY25 * $BG$9*$BG$8^2 -> 28.038089 | BY25: =AZ25 * $BG$9 -> 7.3395657e-06 | BZ25: =BA25 * $BG$9 -> 0.0014323274 | CA25: =BB25 * $BG$9 -> 2.3531092e-05 | CB25: 19
